Workbook

Sheet EST.
A1: RESUMO GERAL DE ESTOQUE
A3: VARIEDADE | B3: PP NEGOCIADO | C3: VALOR NEGOCIADO | D3: R$ PP
A4: Marandú | B4: =SUMIF(B29:B72,"Marandú",E29:E72) -> 682361.39 | C4: =SUMIF(B29:B72,"Marandú",G29:G72) -> 278478.28 | D4: =C4/B4 -> 0.40810966
A5: Piatã | B5: =SUMIF(B29:B72,"Piatã",E29:E72) -> 351971.6 | C5: =SUMIF(B29:B72,"Piatã",G29:G72) -> 101509.04 | D5: =C5/B5 -> 0.28840124
A6: Decumbens | B6: =SUMIF(B29:B72,"Decumbens",E29:E72) -> 1091498.1 | C6: =SUMIF(B29:B72,"Decumbens",G29:G72) -> 352484.07 | D6: =C6/B6 -> 0.32293602
A7: Xaraés | B7: =SUMIF(B29:B72,"Xaraés",E29:E72) -> 2265237.6 | C7: =SUMIF(B29:B72,"Xaraés",G29:G72) -> 640084.25 | D7: =C7/B7 -> 0.28256826
A8: MG-4 | B8: =SUMIF(B29:B72,"MG-4",E29:E72) -> 0 | C8: =SUMIF(B29:B72,"MG-4",G29:G72) -> 0 | D8: =C8/B8 -> #DIV/0!
A9: Ruziziensis | B9: =SUMIF(B29:B72,"Ruziziensis",E29:E72) -> 1143575.3 | C9: =SUMIF(B29:B72,"Ruziziensis",G29:G72) -> 188485.02 | D9: =C9/B9 -> 0.16482082
A10: Humidicola | B10: =SUMIF(B29:B72,"humidicola",E29:E72) -> 729782.79 | C10: =SUMIF(B29:B72,"humidicola",G29:G72) -> 1836631.5 | D10: =C10/B10 -> 2.5166823
A11: Llanero | B11: =SUMIF(B29:B72,"Llanero",E29:E72) -> 10800.98 | C11: =SUMIF(B29:B72,"Llanero",G29:G72) -> 13889 | D11: =C11/B11 -> 1.2859018
A12: Mombaça | B12: =SUMIF(B29:B72,"Mombaça",E29:E72) -> 1539811.4 | C12: =SUMIF(B29:B72,"Mombaça",G29:G72) -> 500205.55 | D12: =C12/B12 -> 0.32484858
A13: Tanzania | B13: =SUMIF(B29:B72,"Tanzania",E29:E72) -> 0 | C13: =SUMIF(B29:B72,"Tanzania",G29:G72) -> 0 | D13: =C13/B13 -> #DIV/0!
A14: Massai | B14: =SUMIF(B29:B72,"Massai",E29:E72) -> 618265.72 | C14: =SUMIF(B29:B72,"Massai",G29:G72) -> 255283.15 | D14: =C14/B14 -> 0.412902
A15: Aruana | B15: =SUMIF(B29:B72,"Aruana",E29:E72) -> 53680.5 | C15: =SUMIF(B29:B72,"Aruana",G29:G72) -> 54405.3 | D15: =C15/B15 -> 1.0135021
A16: Zuri | B16: =SUMIF(B29:B72,"Zuri",E29:E72) -> 1078047.5 | C16: =SUMIF(B29:B72,"Zuri",G29:G72) -> 391649.03 | D16: =C16/B16 -> 0.36329477
A17: Paiaguas | B17: =SUMIF(B29:B72,"Paiaguas",E29:E72) -> 812166.53 | C17: =SUMIF(B29:B72,"Paiaguas",G29:G72) -> 283385.1 | D17: =C17/B17 -> 0.34892487
A18: Tamani | B18: =SUMIF(B29:B72,"Tamani",E29:E72) -> 310983.57 | C18: =SUMIF(B29:B72,"Tamani",G29:G72) -> 199405.07 | D18: =C18/B18 -> 0.64120773
A19: Integra | B19: =SUMIF(B29:B72,"Integra",E29:E72) -> 230333.11 | C19: =SUMIF(B29:B72,"Integra",G29:G72) -> 114890.4 | D19: =C19/B19 -> 0.49880108
A20: Milheto | B20: =SUMIF(B29:B72,"Milheto",E29:E72) -> 2110 | C20: =SUMIF(B29:B72,"Milheto",G29:G72) -> 13166.4 | D20: =C20/B20 -> 6.24
A21: Quenia | B21: =SUMIF(B29:B72,"Quenia",E29:E72) -> 0 | C21: =SUMIF(B29:B72,"Quenia",G29:G72) -> 0 | D21: 0
A22: Estilosante | B22: =SUMIF(B29:B72,"Estilosante",E29:E72) -> 2372 | C22: =SUMIF(B29:B72,"Estilosante",G29:G72) -> 0 | D22: =C22/B22 -> 0
A23: Andropogon | B23: =SUMIF(B29:B72,"Andropogon",E29:E72) -> 0 | C23: =SUMIF(B29:B72,"Andropogon",G29:G72) -> 0 | D23: 0
A24: TOTAIS | B24: =SUM(B4:B23) -> 10922998 | C24: =SUM(C4:C23) -> 5223951.1 | D24: =C24/B24 -> 0.47825249
A26: RELATÓRIO DE ESTOQUE
A28: Data | B28: Cultivar | C28: Fornecedor | D28: Referência | E28: PP | F28: R$/PP | G28: Total R$
A29: 45414 | B29: Marandú | D29: Bruta | E29: =[1]NC!$F$4 -> 286873.71 | F29: =G29/E29 -> 0.25 | G29: ='SAL. '!C63*E29 -> 71718.428
A30: 45414 | B30: Piatã | D30: Bruta | E30: =[1]NC!$F$5 -> 237877.2 | F30: =G30/E30 -> 0.27 | G30: ='SAL. '!C64*E30 -> 64226.844
A31: 45414 | B31: Decumbens | D31: Bruta | E31: =[1]NC!$F$6 -> 1068468.5 | F31: =G31/E31 -> 0.32 | G31: ='SAL. '!C65*E31 -> 341909.92
A32: 45414 | B32: Xaraés | D32: Bruta | E32: =[1]NC!$F$7 -> 1608028.4 | F32: =G32/E32 -> 0.19 | G32: ='SAL. '!C66*E32 -> 305525.4
A33: 45414 | B33: MG-4 | D33: Bruta | E33: =[1]NC!$F$8 -> 0 | F33: 0 | G33: ='SAL. '!C67*E33 -> 0
A34: 45414 | B34: Aruana | D34: Bruta | E34: =[1]NC!$F$15 -> 0 | F34: 0 | G34: ='SAL. '!C74*E34 -> 0
A35: 45414 | B35: Ruziziensis | D35: Bruta | E35: =[1]NC!$F$9 -> 592361.29 | F35: =G35/E35 -> 0.09 | G35: ='SAL. '!C68*E35 -> 53312.516
A36: 45414 | B36: Humidicola | D36: Bruta | E36: =[1]NC!$F$10 -> 722909.32 | F36: =G36/E36 -> 2.5 | G36: ='SAL. '!C69*E36 -> 1807273.3
A37: 45414 | B37: Llanero | D37: Bruta | E37: =[1]NC!$F$11 -> 0 | F37: 0 | G37: ='SAL. '!C70*E37 -> 0
A38: 45414 | B38: Mombaça | D38: Bruta | E38: =[1]NC!$F$12 -> 1237477.2 | F38: =G38/E38 -> 0.26 | G38: ='SAL. '!C71*E38 -> 321744.07
A39: 45414 | B39: Tanzania | D39: Bruta | E39: =[1]NC!$F$13 -> 0 | F39: 0 | G39: ='SAL. '!C72*E39 -> 0
A40: 45414 | B40: Massai | D40: Bruta | E40: =[1]NC!$F$14 -> 495007.85 | F40: =G40/E40 -> 0.3 | G40: ='SAL. '!C73*E40 -> 148502.36
A41: 45414 | B41: Zuri | D41: Bruta | E41: =[1]NC!$F$16 -> 560859.9 | F41: =G41/E41 -> 0.22 | G41: ='SAL. '!C75*E41 -> 123389.18
A42: 45414 | B42: Tamani | D42: Bruta | E42: =[1]NC!$F$18 -> 194188.5 | F42: =G42/E42 -> 0.42 | G42: ='SAL. '!C77*E42 -> 81559.17
A43: 45414 | B43: Integra | D43: Bruta | E43: =[1]NC!$F$20 -> 0.0166 | F43: =G43/E43 -> 0.15 | G43: ='SAL. '!C78*E43 -> 0.00249
...

Sheet DEV.
A1: RESUMO GERAL DE DEVOLUÇÃO
A3: VARIEDADE | B3: PP NEGOCIADO | C3: VALOR NEGOCIADO | D3: R$ PP | E3: PP CHEGADA | F3: R$ PP | G3: % | H3: TOT. FRETE | I3: % | J3: % | K3: DIF.COMP.PP
A4: Marandú | B4: =SUMIF(B26:B98,"Marandu",E26:E98) -> 358245.63 | C4: =SUMIF(B26:B98,"Marandu",G26:G98) -> 156732.24 | D4: =C4/B4 -> 0.43749936 | E4: =SUMIF(B26:B98,"Marandu",I26:I98) -> 358219.92 | F4: =C4/E4 -> 0.43753077 | K4: =SUMIF($B26:$B98,"Marandu",L26:L98) -> -25.7125
A5: Piatã | B5: =SUMIF(B26:B98,"Piatã",E26:E98) -> 51674.024 | C5: =SUMIF(B26:B98,"Piatã",G26:G98) -> 26253.491 | D5: =C5/B5 -> 0.50805975 | E5: =SUMIF(B26:B98,"Piatã",I26:I98) -> 51674.02 | F5: =C5/E5 -> 0.50805979 | K5: =SUMIF($B26:$B98,"Piatã",L26:L98) -> -0.004
A6: Decumbens | B6: =SUMIF(B26:B98,"Decumbens",E26:E98) -> 111176.89 | C6: =SUMIF(B26:B98,"Decumbens",G26:G98) -> 66394.685 | D6: =C6/B6 -> 0.5971986 | E6: =SUMIF(B26:B98,"Decumbens",I26:I98) -> 111176.89 | F6: =C6/E6 -> 0.59719861 | K6: =SUMIF($B26:$B98,"Decumbens",L26:L98) -> -0.002
A7: Xaraes | B7: =SUMIF(B26:B98,"Xaraes",E26:E98) -> 257503.43 | C7: =SUMIF(B26:B98,"Xaraes",G26:G98) -> 155108.07 | D7: =C7/B7 -> 0.60235342 | E7: =SUMIF(B26:B98,"Xaraes",I26:I98) -> 256603.43 | F7: =C7/E7 -> 0.60446609 | K7: =SUMIF($B26:$B98,"Xaraes",L26:L98) -> -900
A8: Tanzania | B8: =SUMIF(B26:B98,"Integra",E26:E98) -> 317883.58 | C8: =SUMIF(B26:B98,"Integra",G26:G98) -> 83791.867 | D8: =C8/B8 -> 0.26359294 | E8: =SUMIF(B26:B98,"Integra",I26:I98) -> 317883.58 | F8: =C8/E8 -> 0.26359294 | K8: =SUMIF($B26:$B98,"Integra",L26:L98) -> 0
A9: Ruziziensis | B9: =SUMIF(B26:B98,"Ruziziensis",E26:E98) -> 823125.15 | C9: =SUMIF(B26:B98,"Ruziziensis",G26:G98) -> 198719.11 | D9: =C9/B9 -> 0.24142028 | E9: =SUMIF(B26:B98,"Ruziziensis",I26:I98) -> 823125.15 | F9: =C9/E9 -> 0.24142028 | K9: =SUMIF($B26:$B98,"Ruziziensis",L26:L98) -> 0
A10: Humidicola | B10: =SUMIF(B26:B98,"humidicola",E26:E98) -> 19652.505 | C10: =SUMIF(B26:B98,"humidicola",G26:G98) -> 74801.78 | D10: =C10/B10 -> 3.8062211 | E10: =SUMIF(B26:B104,"Humidicola",I26:I98) -> 19652.51 | F10: =C10/E10 -> 3.8062202 | K10: =SUMIF($B26:$B98,"Humidicola",L26:L98) -> 0.005
A11: Llanero | B11: =SUMIF(B26:B98,"Llanero",E26:E98) -> 0 | C11: =SUMIF(B26:B98,"Llanero",G26:G98) -> 0 | D11: =C11/B11 -> #DIV/0! | E11: =SUMIF(B26:B98,"Llanero",I26:I98) -> 0 | F11: =C11/E11 -> #DIV/0! | K11: =SUMIF($B26:$B98,"Llanero",L26:L98) -> 0
A12: Mombaça | B12: =SUMIF(B26:B98,"Mombaça",E26:E98) -> 256725 | C12: =SUMIF(B26:B98,"Mombaça",G26:G98) -> 217431.06 | D12: =C12/B12 -> 0.8469415 | E12: =SUMIF(B26:B98,"Mombaça",I26:I98) -> 256725 | F12: =C12/E12 -> 0.8469415 | K12: =SUMIF($B26:$B98,"Mombaça",L26:L98) -> 0
A13: Paiaguas | B13: =SUMIF(B26:B98,"Paiaguas",E26:E98) -> 107133.57 | C13: =SUMIF(B26:B98,"Paiaguas",G26:G98) -> 106893.04 | D13: =C13/B13 -> 0.99775488 | E13: =SUMIF(B26:B98,"Paiaguas",I26:I98) -> 107133.57 | F13: =C13/E13 -> 0.99775488 | K13: =SUMIF($B26:$B98,"Ipyporã",L26:L98) -> 0
A14: Massai | B14: =SUMIF(B26:B98,"Massai",E26:E98) -> 57662.428 | C14: =SUMIF(B26:B98,"Massai",G26:G98) -> 37845.154 | D14: =C14/B14 -> 0.65632259 | E14: =SUMIF(B26:B98,"Massai",I26:I98) -> 57662.43 | F14: =C14/E14 -> 0.65632257 | K14: =SUMIF($B26:$B98,"Massai",L26:L98) -> 0.002
A15: Aruana | B15: =SUMIF(B26:B98,"Aruana",E26:E98) -> 8437.5 | C15: =SUMIF(B26:B98,"Aruana",G26:G98) -> 9007.5 | D15: =C15/B15 -> 1.0675556 | E15: =SUMIF(B26:B98,"Aruana",I26:I98) -> 8437.5 | F15: =C15/E15 -> 1.0675556 | K15: =SUMIF($B26:$B98,"Aruana",L26:L98) -> 0
A16: Zuri | B16: =SUMIF(B26:B98,"Zuri",E26:E98) -> 57829.997 | C16: =SUMIF(B26:B98,"Zuri",G26:G98) -> 52238.028 | D16: =C16/B16 -> 0.90330331 | E16: =SUMIF(B26:B98,"Zuri",I26:I98) -> 57492.5 | F16: =C16/E16 -> 0.90860595 | K16: =SUMIF($B26:$B98,"Zuri",L26:L98) -> -337.497
A17: Quenia | B17: =SUMIF(B26:B98,"Quenia",E26:E98) -> 0 | C17: =SUMIF(B26:B98,"Quenia",G26:G98) -> 0 | D17: =C17/B17 -> #DIV/0! | E17: =SUMIF(B26:B98,"Quenia",I26:I98) -> 0 | F17: =C17/E17 -> #DIV/0! | K17: =SUMIF($B26:$B98,"Quenia",L26:L98) -> 0
A18: Tamani | B18: =SUMIF(B26:B98,"Tamani",E26:E98) -> 148873.63 | C18: =SUMIF(B26:B98,"Tamani",G26:G98) -> 123309.3 | D18: =C18/B18 -> 0.8282817 | E18: =SUMIF(B26:B98,"Tamani",I26:I98) -> 148873.63 | F18: =C18/E18 -> 0.82828168 | K18: =SUMIF($B26:$B98,"Tamani",L26:L98) -> 0.004
A19: Milheto | B19: =SUMIF(B26:B98,"Milheto",E26:E98) -> 2050 | C19: =SUMIF(B26:B98,"Milheto",G26:G98) -> 12792 | D19: =C19/B19 -> 6.24 | E19: =SUMIF(B26:B98,"Milheto",I26:I98) -> 2050 | F19: =C19/E19 -> 6.24 | K19: =SUMIF($B26:$B98,"Milheto",L26:L98) -> 0
A20: Estilosante | B20: =SUMIF(B26:B98,"Estilosante",E26:E98) -> 0 | C20: =SUMIF(B26:B98,"Estilosantes",G26:G98) -> 0 | D20: =C20/B20 -> #DIV/0! | E20: =SUMIF(B26:B98,"Estilosante",I26:I98) -> 0 | F20: =C20/E20 -> #DIV/0! | K20: =SUMIF($B26:$B98,"Estilosantes",L26:L98) -> 0
A21: TOTAIS | B21: =SUM(B4:B20) -> 2577973.3 | C21: =SUM(C4:C20) -> 1321317.3 | D21: =C21/B21 -> 0.51254111 | E21: =SUM(E4:E20) -> 2576710.1 | F21: =C21/E21 -> 0.51279238 | K21: =SUM(K4:K20) -> -1263.2045
A23: RELATÓRIO DE ESTOQUE
A25: Data | B25: Cultivar | C25: Fornecedor | D25: Pureza NF | E25: PP NFE | F25: R$/PP/NFE | G25: Total R$ | H25: KG NFE | I25: PP Real | J25: Kg Real | K25: Pureza Real | L25: Dif.Com | M25: R$/PP/Real | N25: Dif.Com
A26: 45413 | B26: Marandu | C26: Tecidos e Armarinhos Miguel Bartolomeu | D26: 25.71 | E26: =H26*D26 -> 385.65 | F26: =G26/E26 -> 0.61610268 | G26: 237.6 | H26: 15 | I26: 359.94 | J26: 14 | K26: =I26/J26 -> 25.71 | L26: =I26-E26 -> -25.71 | M26: =G26/I26 -> 0.66011002 | N26: =J26-H26 -> -1
A27: 45413 | B27: Ruziziensis | C27: Mercedes Abid Mercante | D27: 38.3 | E27: =H27*D27 -> 19533 | F27: =G27/E27 -> 0.35535248 | G27: 6941.1 | H27: 510 | I27: 19533 | J27: 510 | K27: =I27/J27 -> 38.3 | L27: =I27-E27 -> 0 | M27: =G27/I27 -> 0.35535248 | N27: =J27-H27 -> 0
A28: 45413 | B28: Ruziziensis | C28: Basso & Pancotte Ltda | D28: 25.71 | E28: =H28*D28 -> 385.65 | F28: =G28/E28 -> 0.39867756 | G28: 153.75 | H28: 15 | I28: 385.65 | J28: 15 | K28: =I28/J28 -> 25.71 | L28: =I28-E28 -> 0 | M28: =G28/I28 -> 0.39867756 | N28: =J28-H28 -> 0
A29: 45413 | B29: Mombaça | C29: Max Farming - Distribuição de Produtos | D29: 37.5 | E29: =H29*D29 -> 1687.5 | F29: =G29/E29 -> 0.844 | G29: 1424.25 | H29: 45 | I29: 1687.5 | J29: 45 | K29: =I29/J29 -> 37.5 | L29: =I29-E29 -> 0 | M29: =G29/I29 -> 0.844 | N29: =J29-H29 -> 0
A30: 45413 | B30: Milheto | C30: Lageado Produtos Agropecuarios - Eireli | D30: 1 | E30: =H30*D30 -> 2050 | F30: =G30/E30 -> 6.24 | G30: 12792 | H30: 2050 | I30: 2050 | J30: 2050 | K30: =I30/J30 -> 1 | L30: =I30-E30 -> 0 | M30: =G30/I30 -> 6.24 | N30: =J30-H30 -> 0
A31: 45413 | B31: Piatã | C31: Lageado Produtos Agropecuarios - Eireli | D31: 45 | E31: =H31*D31 -> 2025 | F31: =G31/E31 -> 0.56111111 | G31: 1136.25 | H31: 45 | I31: 2025 | J31: 45 | K31: =I31/J31 -> 45 | L31: =I31-E31 -> 0 | M31: =G31/I31 -> 0.56111111 | N31: =J31-H31 -> 0
A32: 45413 | B32: Zuri | C32: Lageado Produtos Agropecuarios - Eireli | D32: 37.5 | E32: =H32*D32 -> 2250 | F32: =G32/E32 -> 1.0005333 | G32: 2251.2 | H32: 60 | I32: 2250 | J32: 60 | K32: =I32/J32 -> 37.5 | L32: =I32-E32 -> 0 | M32: =G32/I32 -> 1.0005333 | N32: =J32-H32 -> 0
A33: 45413 | B33: Zuri | C33: Lageado Produtos Agropecuarios - Eireli | D33: 22.5 | E33: =H33*D33 -> 1687.5 | F33: =G33/E33 -> 1.0675556 | G33: 1801.5 | H33: 75 | I33: 1687.5 | J33: 75 | K33: =I33/J33 -> 22.5 | L33: =I33-E33 -> 0 | M33: =G33/I33 -> 1.0675556 | N33: =J33-H33 -> 0
A34: 45413 | B34: Massai | C34: Brascampo Produtos Agropecuarios Ltda | D34: 22.5 | E34: =H34*D34 -> 337.5 | F34: =G34/E34 -> 1.2271111 | G34: 414.15 | H34: 15 | I34: 337.5 | J34: 15 | K34: =I34/J34 -> 22.5 | L34: =I34-E34 -> 0 | M34: =G34/I34 -> 1.2271111 | N34: =J34-H34 -> 0
A35: 45413 | B35: Ruziziensis | C35: Nativa Agricultura Sustentável Ltda | D35: 38.3 | E35: =H35*D35 -> 126390 | F35: =G35/E35 -> 0.35535248 | G35: 44913 | H35: 3300 | I35: 126390 | J35: 3300 | K35: =I35/J35 -> 38.3 | L35: =I35-E35 -> 0 | M35: =G35/I35 -> 0.35535248 | N35: =J35-H35 -> 0
A36: 45413 | B36: Ruziziensis | C36: Agro Directa Produtos Agricolas Ltda | D36: 38.3 | E36: =H36*D36 -> 124666.5 | F36: =G36/E36 -> 0.35535248 | G36: 44300.55 | H36: 3255 | I36: 124666.5 | J36: 3255 | K36: =I36/J36 -> 38.3 | L36: =I36-E36 -> 0 | M36: =G36/I36 -> 0.35535248 | N36: =J36-H36 -> 0
A37: 45433 | B37: Paiaguas | C37: Ermilio Paludo | D37: 25.71 | E37: =H37*D37 -> 90627.75 | F37: =G37/E37 -> 1.1015169 | G37: 99828 | H37: 3525 | I37: 90627.75 | J37: 3525 | K37: =I37/J37 -> 25.71 | L37: =I37-E37 -> 0 | M37: =G37/I37 -> 1.1015169 | N37: =J37-H37 -> 0
... A76: 45489 | B76: Aruana | C76: A.Torres da Paz & Cia Ltda - EPP | D76: 22.5 | E76: =H76*D76 -> 1012.5 | F76: =G76/E76 -> 1.0675556 | G76: 1080.9 | H76: 45 | I76: 1012.5 | J76: 45 | K76: =I76/J76 -> 22.5 | L76: =I76-E76 -> 0 | M76: =G76/I76 -> 1.0675556 | N76: =J76-H76 -> 0
B77: Mombaça | D77: 37.5 | E77: =H77*D77 -> 32625 | F77: =VEN!P37 -> 0.43084314 | G77: =E77*F77 -> 14056.257 | H77: 870 | I77: 32625 | J77: 870 | K77: =I77/J77 -> 37.5 | L77: =I77-E77 -> 0 | M77: =G77/I77 -> 0.43084314 | N77: =J77-H77 -> 0
A78: 45755 | B78: Massai | D78: 37.788 | E78: =H78*D78 -> 29512.428 | F78: =VEN!P43 -> 0.59738116 | G78: =E78*F78 -> 17630.169 | H78: 781 | I78: 29512.43 | J78: 781 | K78: =I78/J78 -> 37.788003 | L78: =I78-E78 -> 0.002 | M78: =G78/I78 -> 0.59738112 | N78: =J78-H78 -> 0
A79: 45755 | B79: Integra | D79: 38.29 | E79: =H79*D79 -> 317883.58 | F79: =VEN!P60 -> 0.26359294 | G79: =E79*F79 -> 83791.867 | H79: 8302 | I79: 317883.58 | J79: 8302 | K79: =I79/J79 -> 38.29 | L79: =I79-E79 -> 0 | M79: =G79/I79 -> 0.26359294 | N79: =J79-H79 -> 0
A80: 45755 | B80: Paiaguas | D80: 25.71 | E80: =H80*D80 -> 16505.82 | F80: =VEN!P54 -> 0.4280334 | G80: =E80*F80 -> 7065.0422 | H80: 642 | I80: 16505.82 | J80: 642 | K80: =I80/J80 -> 25.71 | L80: =I80-E80 -> 0 | M80: =G80/I80 -> 0.4280334 | N80: =J80-H80 -> 0
A81: 45755 | B81: Ruziziensis | D81: 32.72 | E81: =H81*D81 -> 552150 | F81: =VEN!P25 -> 0.18547624 | G81: =E81*F81 -> 102410.71 | H81: 16875 | I81: 552150 | J81: 16875 | K81: =I81/J81 -> 32.72 | L81: =I81-E81 -> 0 | M81: =G81/I81 -> 0.18547624 | N81: =J81-H81 -> 0
...

Sheet PRO.
A1: RESUMO GERAL DE PRODUÇÃO
A3: VARIEDADE | B3: PP CARGA | C3: PP/R$ | D3: VALOR
A4: Marandú | B4: =SUMIF(B20:B48,"Marandu",H20:H48) -> 327876.5 | D4: =SUMIF($B$20:$B$48,"Marandu",J20:J48) -> 18791.76 | E4: =D4/B4 -> 0.057313531
A5: Piatã | B5: =SUMIF(B20:B48,"Piatã",H20:H48) -> 308460 | D5: =SUMIF($B$20:$B$48,"Piatã",J20:J48) -> 15393.84 | E5: =D5/B5 -> 0.049905466
A6: Xaraes | B6: =SUMIF(B20:B48,"Xaraes",H20:H48) -> 853106.7 | D6: =SUMIF($B$20:$B$48,"Xaraes",$J$20:SJ$48) -> 40659.84 | E6: =D6/B6 -> 0.047660908
A7: Ruziziensis | B7: =SUMIF(B20:B48,"Ruziziensis",H20:H48) -> 9203724 | D7: =SUMIF($B$20:$B$48,"Ruziziensis",$J$20:SJ$48) -> 358969.44 | E7: =D7/B7 -> 0.03900263
A8: Integra | B8: =SUMIF(B20:B48,"Integra",H20:H48) -> 12700965 | D8: =SUMIF($B$20:$B$48,"Integra",$J$20:SJ$48) -> 412950.03 | E8: =D8/B8 -> 0.03251328
A9: Mombaça | B9: =SUMIF(B20:B48,"Mombaça",H20:H48) -> 74424.1 | D9: =SUMIF($B$20:$B$48,"Mombaça",$J$20:SJ$48) -> 3955.2 | E9: =D9/B9 -> 0.053144076
A10: Sarandi | B10: =SUMIF(B20:B48,"Sarandi",H20:H48) -> 10300 | D10: =SUMIF($B$20:$B$48,"Sarandi",J20:J48) -> 15738 | E10: =D10/B10 -> 1.5279612
A11: Zuri | B11: =SUMIF(B20:B48,"Zuri",H20:H48) -> 1198233.4 | D11: =SUMIF($B$20:$B$48,"Zuri",J20:J48) -> 261728.61 | E11: =D11/B11 -> 0.21842874
A12: Sudão | B12: =SUMIF(B20:B48,"Sudão",H20:H48) -> 17082 | D12: =SUMIF($B$20:$B$48,"Sudão",$J$20:SJ$48) -> 243632.13 | E12: =D12/B12 -> 14.262506
A13: Estilosantes | B13: =SUMIF(B20:B48,"Estilosantes",H20:H48) -> 19660 | D13: =SUMIF($B$20:$B$48,"Estilosantes",J20:J48) -> 88299 | E13: =D13/B13 -> 4.4913021
A14: TOTAIS | B14: =SUM(B4:B13) -> 24713832 | C14: =MEDIAN(C4:C13) -> #VALUE! | D14: =SUM(D4:D13) -> 1460117.9 | E14: =D14/B14 -> 0.059080999 | G14: =SUM(G4:G13) -> 0 | H14: =SUM(H4:H13) -> 0 | I14: =SUM(I4:I13) -> 0 | J14: =SUM(J4:J13) -> 0 | K14: =SUM(K4:K13) -> 0
B15: PUREZA
B16: =M49 -> 80.081818
A17: RELATÓRIO DE PRODUÇÃO
A19: Data | B19: Cultivar | C19: Fornecedor | D19: Motorista | E19: Pureza | F19: Tz | G19: Carga | H19: PP Carga | I19: Peso Carga | J19: Valor | K19: NF | L19: Beneficiamento | M19: PP Beneficiamento
A20: 45469 | B20: Zuri | C20: Salto Belo | D20: Aparecido | E20: 77.8 | G20: 014/24 | H20: =E20*I20 -> 535030.6 | I20: 6877 | J20: 113676.81 | K20: 359 | M20: 77.8
A21: 45470 | B21: Zuri | C21: Salto Belo | D21: Salvador | E21: 76.6 | G21: 015/24 | H21: =E21*I21 -> 663202.8 | I21: 8658 | J21: 148051.8 | K21: 360 | M21: 76.6
A22: 45470 | B22: Sudão | C22: Barigajau | D22: Salvador | E22: 1 | G22: 016/24 | H22: =E22*I22 -> 16237 | I22: 16237 | J22: 243555 | K22: 512 | M22: 90.5
A23: 45485 | B23: Ruziziensis | C23: Shangrila | D23: Salvador | E23: 86.2 | F23: 84 | G23: 020/24 | H23: =E23*I23 -> 1625732 | I23: 18860 | J23: 49612.8 | K23: 37 | M23: 86.2
A24: 45485 | B24: Integra | C24: Serra Azul | D24: Salvador | E24: 79.2 | F24: 88 | G24: 021/24 | H24: =E24*I24 -> 1580832 | I24: 19960 | J24: 51624.75 | K24: 95 | M24: 79.2
A25: 45496 | B25: Integra | C25: Serra Azul | D25: Gustavo | E25: 76.9 | F25: 80 | G25: 024/24 | H25: =E25*I25 -> 2905282 | I25: 37780 | J25: 92719.2 | K25: 99 | M25: 76.9
A26: 45504 | B26: Integra | C26: Serra Azul | D26: Salvador | E26: 82.1 | F26: 78 | G26: 029/24 | H26: =E26*I26 -> 3049194 | I26: 37140 | J26: 86400 | K26: 105 | M26: 82.1
A27: 45514 | B27: Marandu | C27: Barigajau | D27: Salvador | E27: 80.5 | G27: 038/24 | H27: =E27*I27 -> 327876.5 | I27: 4073 | J27: 18791.76 | K27: 538 | M27: 80.5
A28: 45514 | B28: Xaraes | C28: Barigajau | D28: Salvador | E28: 84.1 | G28: 039/24 | H28: =E28*I28 -> 310076.7 | I28: 3687 | J28: 18234.72 | K28: 538 | M28: 84.1
A29: 45514 | B29: Sudão | C29: Barigajau | D29: Salvador | E29: 1 | G29: 040/24 | H29: =E29*I29 -> 845 | I29: 845 | J29: 77.13 | K29: 538 | M29: 92.9
A30: 45514 | B30: Mombaça | C30: Salto Belo | D30: Salvador | E30: 75.1 | G30: 041/24 | H30: =E30*I30 -> 74424.1 | I30: 991 | J30: 3955.2 | K30: 376 | M30: 75.1
A31: 45514 | B31: Integra | C31: Salto Belo | D31: Salvador | E31: 76.3 | F31: 75 | G31: 042/24 | H31: =E31*I31 -> 101936.8 | I31: 1336 | J31: 4466.88 | K31: 376 | M31: 76.3
A32: 45514 | B32: Integra | C32: Serra Azul | D32: Salvador | E32: 74.6 | F32: 75 | G32: 043/24 | H32: =E32*I32 -> 1451716 | I32: 19460 | J32: 50918.4 | K32: 114 | M32: 74.6
A33: 45531 | B33: Xaraes | C33: Barigajau | D33: Gustavo | E33: 78.7 | G33: 052/24 | H33: =E33*I33 -> 543030 | I33: 6900 | J33: 22425.12 | K33: 543 | M33: 78.7
A34: 45531 | B34: Estilosantes | C34: Barigajau | D34: Gustavo | E34: 1 | G34: 053/24 | H34: =E34*I34 -> 19660 | I34: 19660 | J34: 88299 | K34: 543 | M34: 90.2
A35: 45532 | B35: Ruziziensis | C35: Barigajau | D35: Salvador | E35: 82.6 | F35: 50 | G35: 054/24 | H35: =E35*I35 -> 2781968 | I35: 33680 | J35: 168750 | K35: 548 | M35: 82.6
A36: 45544 | B36: Ruziziensis | C36: Serra Azul | D36: Salvador | E36: 81.3 | F36: 42 | G36: 060/24 | H36: =E36*I36 -> 3079644 | I36: 37880 | J36: 83244.24 | K36: 129 | M36: 81.3
A37: 45544 | B37: Integra | C37: Serra Azul | D37: Gustavo | E37: 79.7 | F37: 78 | G37: 061/24 | H37: =E37*I37 -> 2383030 | I37: 29900 | J37: 93600 | K37: 128 | M37: 79.7
A38: 45548 | B38: Sarandi | C38: Salto Belo | D38: Salvador | E38: 1 | G38: 062/24 | H38: =E38*I38 -> 6160 | I38: 6160 | J38: 9412.5 | K38: 387
A39: 45548 | B39: Sarandi | C39: Salto Belo | D39: Gustavo | E39: 1 | G39: 063/24 | H39: =E39*I39 -> 2160 | I39: 2160 | J39: 3133.5 | K39: 385
A40: 45548 | B40: Sarandi | C40: Salto Belo | D40: Gustavo | E40: 1 | G40: 064/24 | H40: =E40*I40 -> 320 | I40: 320 | J40: 600 | K40: 384
A41: 45548 | B41: Sarandi | C41: Salto Belo | D41: Gustavo | E41: 1 | G41: 065/24 | H41: =E41*I41 -> 1660 | I41: 1660 | J41: 2592 | K41: 389
A42: 45611 | B42: Ruziziensis | C42: Serra Azul | D42: Luciano | E42: 68.2 | F42: 56 | G42: 107/24 | H42: =E42*I42 -> 737924 | I42: 10820 | J42: 23198.4 | K42: 147 | M42: 68.2
...

Sheet PAR.
A1: RESUMO GERAL DE PARCEIROS
A3: VARIEDADE | B3: PP NEGOCIADO | C3: R$ PP | D3: VALOR NEGOCIADO | E3: PP NOSSO | F3: TOT. COMIS | I3: % | J3: TOT. FRETE | K3: % | L3: TOT. ICMS | M3: % | N3: TOT.DIF.COMP. | O3: QUEBRA | P3: % QUEBRA | Q3: TOT.ESTETICA | R3: % EST. | S3: PP PRONTO | T3: VALOR PAGO | U3: R$ PP REAL | V3: PP RECEBIDO | W3: PP A RECEBER
A4: Marandú | B4: =SUMIF(B26:B48,"Marandu",E26:E48) -> 0 | C4: 0 | D4: =C4*B4 -> 0 | E4: =SUMIF(B26:B48,"Marandu",K26:K48) -> 0 | F4: =SUMIF(B26:B48,"Marandu",L26:L48) -> 0 | I4: =F4/C4 -> #DIV/0! | J4: =SUMIF(B26:B48,"Marandu",N26:N48) -> 0 | K4: =J4/C4 -> #DIV/0! | L4: =SUMIF($B26:$B48,"Marandu",P26:P48) -> 0 | M4: =L4/C4 -> #DIV/0! | N4: =SUMIF($B26:$B48,"Marandu",R26:R48) -> 0 | O4: =SUMIF($B26:$B48,"Marandu",S26:S48) -> 0 | P4: =O4/E4 -> #DIV/0! | Q4: =SUMIF($B26:$B48,"Marandu",U26:U48) -> 0 | R4: =Q4/C4 -> #DIV/0! | S4: =SUMIF($B26:$B48,"Marandu",W26:W48) -> 0 | T4: =SUMIF($B26:$B48,"Marandu",X26:X48) -> 0 | U4: =T4/S4 -> #DIV/0! | V4: =SUMIF($B26:$B48,"Marandu",Z26:Z48) -> 0 | W4: =SUMIF($B26:$B48,"Marandu",AA26:AA48) -> 0
A5: Piatã | B5: =SUMIF(B26:B48,"Piatã",E26:E48) -> 0 | C5: =SUMIF(B26:B48,"Piatã",I26:I48) -> 0 | D5: =C5*B5 -> 0 | E5: =SUMIF(B26:B48,"Piatã",K26:K48) -> 0 | F5: =SUMIF(B26:B48,"Piata",L26:L48) -> 0 | I5: =F5/C5 -> #DIV/0! | J5: =SUMIF(B26:B48,"Piata",N26:N48) -> 0 | K5: =J5/C5 -> #DIV/0! | L5: =SUMIF($B26:$B48,"Piata",P26:P48) -> 0 | M5: =L5/C5 -> #DIV/0! | N5: =SUMIF($B26:$B48,"Piatã",R26:R48) -> 0 | O5: =SUMIF($B26:$B48,"Piatã",S26:S48) -> 0 | P5: =O5/E5 -> #DIV/0! | Q5: =SUMIF($B26:$B48,"Piatã",U26:U48) -> 0 | R5: =Q5/C5 -> #DIV/0! | S5: =SUMIF($B26:$B48,"Piatã",W26:W48) -> 0 | T5: =SUMIF($B26:$B48,"Piatã",X26:X48) -> 0 | U5: =T5/S5 -> #DIV/0! | V5: =SUMIF($B26:$B48,"Piatã",Z26:Z48) -> 0 | W5: =SUMIF($B26:$B48,"Piatã",AA26:AA48) -> 0
A6: Decumbens | B6: =SUMIF(B26:B48,"Decumbens",E26:E48) -> 0 | C6: =SUMIF(B26:B48,"Decumbens",I26:I48) -> 0 | D6: =C6*B6 -> 0 | E6: =SUMIF(B26:B48,"Decumbens",K26:K48) -> 0 | F6: =SUMIF(B26:B48,"Decumbens",L26:L48) -> 0 | I6: =F6/C6 -> #DIV/0! | J6: =SUMIF(B26:B48,"Decumbens",N26:N48) -> 0 | K6: =J6/C6 -> #DIV/0! | L6: =SUMIF($B26:$B48,"Decumbens",P26:P48) -> 0 | M6: =L6/C6 -> #DIV/0! | N6: =SUMIF($B26:$B48,"Decumbens",R26:R48) -> 0 | O6: =SUMIF($B26:$B48,"Decumbens",S26:S48) -> 0 | P6: =O6/E6 -> #DIV/0! | Q6: =SUMIF($B26:$B48,"Decumbens",U26:U48) -> 0 | R6: =Q6/C6 -> #DIV/0! | S6: =SUMIF($B26:$B48,"Decumbens",W26:W48) -> 0 | T6: =SUMIF($B26:$B48,"Decumbens",X26:X48) -> 0 | U6: =T6/S6 -> #DIV/0! | V6: =SUMIF($B26:$B48,"Decumbens",Z26:Z48) -> 0 | W6: =SUMIF($B26:$B48,"Decumbens",AA26:AA48) -> 0
A7: MG-5 | B7: =SUMIF(B26:B48,"MG-5",E26:E48) -> 0 | C7: ='SAL.(3)'!C62 -> 0 | D7: =C7*B7 -> 0 | E7: =SUMIF(B26:B48,"MG-5",K26:K48) -> 0 | F7: =SUMIF(B26:B48,"MG-5",L26:L48) -> 0 | I7: =F7/C7 -> #DIV/0! | J7: =SUMIF(B26:B48,"MG-5",N26:N48) -> 0 | K7: =J7/C7 -> #DIV/0! | L7: =SUMIF($B26:$B48,"MG-5",P26:P48) -> 0 | M7: =L7/C7 -> #DIV/0! | N7: =SUMIF($B26:$B48,"MG-5",R26:R48) -> 0 | O7: =SUMIF($B26:$B48,"MG-5",S26:S48) -> 0 | P7: =O7/E7 -> #DIV/0! | Q7: =SUMIF($B26:$B48,"MG-5",U26:U48) -> 0 | R7: =Q7/C7 -> #DIV/0! | S7: =SUMIF($B26:$B48,"MG-5",W26:W48) -> 0 | T7: =SUMIF($B26:$B48,"MG-5",X26:X48) -> 0 | U7: =T7/S7 -> #DIV/0! | V7: =SUMIF($B26:$B48,"MG-5",Z26:Z48) -> 0 | W7: =SUMIF($B26:$B48,"MG-5",AA26:AA48) -> 0
A8: MG-4 | B8: =SUMIF(B26:B48,"MG-4",E26:E48) -> 0 | C8: =SUMIF(B26:B48,"MG-4",I26:I48) -> 0 | D8: =C8*B8 -> 0 | E8: =SUMIF(B26:B48,"MG-4",K26:K48) -> 0 | F8: =SUMIF(B26:B48,"MG-4",L26:L48) -> 0 | I8: =F8/C8 -> #DIV/0! | J8: =SUMIF(B26:B48,"MG-4",N26:N48) -> 0 | K8: =J8/C8 -> #DIV/0! | L8: =SUMIF($B26:$B48,"MG-4",P26:P48) -> 0 | M8: =L8/C8 -> #DIV/0! | N8: =SUMIF($B26:$B48,"MG-4",R26:R48) -> 0 | O8: =SUMIF($B26:$B48,"MG-4",S26:S48) -> 0 | P8: =O8/E8 -> #DIV/0! | Q8: =SUMIF($B26:$B48,"MG-4",U26:U48) -> 0 | R8: =Q8/C8 -> #DIV/0! | S8: =SUMIF($B26:$B48,"MG-4",W26:W48) -> 0 | T8: =SUMIF($B26:$B48,"MG-4",X26:X48) -> 0 | U8: =T8/S8 -> #DIV/0! | V8: =SUMIF($B26:$B48,"MG-4",Z26:Z48) -> 0 | W8: =SUMIF($B26:$B48,"MG-4",AA26:AA48) -> 0
A9: Ruziziensis | B9: =SUMIF(B26:B48,"Ruziziensis",E26:E48) -> 17194804 | C9: ='SAL.(3)'!C64 -> 0 | D9: =C9*B9 -> 0 | E9: =SUMIF(B26:B48,"Ruziziensis",K26:K48) -> 17194804 | F9: =SUMIF(B26:B48,"Ruziziensis",L26:L48) -> 0 | I9: =F9/C9 -> #DIV/0! | J9: =SUMIF(B26:B48,"Ruziziensis",N26:N48) -> 0 | K9: =J9/C9 -> #DIV/0! | L9: =SUMIF($B26:$B48,"Ruziziensis",P26:P48) -> 0 | M9: =L9/C9 -> #DIV/0! | N9: =SUMIF($B26:$B48,"Ruziziensis",R26:R48) -> 0 | O9: =SUMIF($B26:$B48,"Ruziziensis",S26:S48) -> 0 | P9: =O9/E9 -> 0 | Q9: =SUMIF($B26:$B48,"Ruziziensis",U26:U48) -> 0 | R9: =Q9/C9 -> #DIV/0! | S9: =SUMIF($B26:$B48,"Ruziziensis",W26:W48) -> 17194804 | T9: =SUMIF($B26:$B48,"Ruziziensis",X26:X48) -> 0 | U9: =T9/S9 -> 0 | V9: =SUMIF($B26:$B48,"Ruziziensis",Z26:Z48) -> 17194804 | W9: =SUMIF($B26:$B48,"Ruziziensis",AA26:AA48) -> 0
A10: Humidicola | B10: =SUMIF(B26:B48,"humidicola",E26:E48) -> 0 | C10: =SUMIF(B26:B48,"humidicola",I26:I48) -> 0 | D10: =C10*B10 -> 0 | E10: =SUMIF(B26:B54,"Humidicola",K26:K48) -> 0 | F10: =SUMIF(B26:B48,"humidicola",L26:L48) -> 0 | I10: =F10/C10 -> #DIV/0! | J10: =SUMIF(B26:B48,"humidicola",N26:N48) -> 0 | K10: =J10/C10 -> #DIV/0! | L10: =SUMIF($B26:$B48,"Humidicola",P26:P48) -> 0 | M10: =L10/C10 -> #DIV/0! | N10: =SUMIF($B26:$B48,"Humidicola",R26:R48) -> 0 | O10: =SUMIF($B26:$B48,"Humidicola",S26:S48) -> 0 | P10: =O10/E10 -> #DIV/0! | Q10: =SUMIF($B26:$B48,"Humidicola",U26:U48) -> 0 | R10: =Q10/C10 -> #DIV/0! | S10: =SUMIF($B26:$B48,"Humidicola",W26:W48) -> 0 | T10: =SUMIF($B26:$B48,"Humidicola",X26:X48) -> 0 | U10: =T10/S10 -> #DIV/0! | V10: =SUMIF($B26:$B48,"Humidicola",Z26:Z48) -> 0 | W10: =SUMIF($B26:$B48,"Humidicola",AA26:AA48) -> 0
A11: Llanero | B11: =SUMIF(B26:B48,"Llanero",E26:E48) -> 0 | C11: =SUMIF(B26:B48,"Llanero",I26:I48) -> 0 | D11: =C11*B11 -> 0 | E11: =SUMIF(B26:B48,"Llanero",K26:K48) -> 0 | F11: =SUMIF(B26:B48,"Llanero",L26:L48) -> 0 | I11: =F11/C11 -> #DIV/0! | J11: =SUMIF(B26:B48,"Llanero",N26:N48) -> 0 | K11: =J11/C11 -> #DIV/0! | L11: =SUMIF($B26:$B48,"Llanero",P26:P48) -> 0 | M11: =L11/C11 -> #DIV/0! | N11: =SUMIF($B26:$B48,"Llanero",R26:R48) -> 0 | O11: =SUMIF($B26:$B48,"Llanero",S26:S48) -> 0 | P11: =O11/E11 -> #DIV/0! | Q11: =SUMIF($B26:$B48,"Llanero",U26:U48) -> 0 | R11: =Q11/C11 -> #DIV/0! | S11: =SUMIF($B26:$B48,"Llanero",W26:W48) -> 0 | T11: =SUMIF($B26:$B48,"Llanero",X26:X48) -> 0 | U11: =T11/S11 -> #DIV/0! | V11: =SUMIF($B26:$B48,"Llanero",Z26:Z48) -> 0 | W11: =SUMIF($B26:$B48,"Llanero",AA26:AA48) -> 0
A12: Mombaça | B12: =SUMIF(B26:B48,"Mombaça",E26:E48) -> 0 | C12: ='SAL.(3)'!C67 -> 0 | D12: =C12*B12 -> 0 | E12: =SUMIF(B26:B48,"Mombaça",K26:K48) -> 0 | F12: =SUMIF(B26:B48,"Mombaça",L26:L48) -> 0 | I12: =F12/C12 -> #DIV/0! | J12: =SUMIF(B26:B48,"Mombaça",N26:N48) -> 0 | K12: =J12/C12 -> #DIV/0! | L12: =SUMIF($B26:$B48,"Mombaça",P26:P48) -> 0 | M12: =L12/C12 -> #DIV/0! | N12: =SUMIF($B26:$B48,"Mombaça",R26:R48) -> 0 | O12: =SUMIF($B26:$B48,"Mombaça",S26:S48) -> 0 | P12: =O12/E12 -> #DIV/0! | Q12: =SUMIF($B26:$B48,"Mombaça",U26:U48) -> 0 | R12: =Q12/C12 -> #DIV/0! | S12: =SUMIF($B26:$B48,"Mombaça",W26:W48) -> 0 | T12: =SUMIF($B26:$B48,"Mombaça",X26:X48) -> 0 | U12: =T12/S12 -> #DIV/0! | V12: =SUMIF($B26:$B48,"Mombaça",Z26:Z48) -> 0 | W12: =SUMIF($B26:$B48,"Mombaça",AA26:AA48) -> 0
A13: Tanzania | B13: =SUMIF(B26:B48,"Tanzania",E26:E48) -> 0 | C13: =SUMIF(B26:B48,"Tanzania",I26:I48) -> 0 | D13: =C13*B13 -> 0 | E13: =SUMIF(B26:B48,"Tanzania",K26:K48) -> 0 | F13: =SUMIF(B26:B48,"Tanzania",L26:L48) -> 0 | I13: =F13/C13 -> #DIV/0! | J13: =SUMIF(B26:B48,"Tanzania",N26:N48) -> 0 | K13: =J13/C13 -> #DIV/0! | L13: =SUMIF($B26:$B48,"Tanzania",P26:P48) -> 0 | M13: =L13/C13 -> #DIV/0! | N13: =SUMIF($B26:$B48,"Tanzania",R26:R48) -> 0 | O13: =SUMIF($B26:$B48,"Tanzania",S26:S48) -> 0 | P13: =O13/E13 -> #DIV/0! | Q13: =SUMIF($B26:$B48,"Tanzania",U26:U48) -> 0 | R13: =Q13/C13 -> #DIV/0! | S13: =SUMIF($B26:$B48,"Tanzania",W26:W48) -> 0 | T13: =SUMIF($B26:$B48,"Tanzania",X26:X48) -> 0 | U13: =T13/S13 -> #DIV/0! | V13: =SUMIF($B26:$B48,"Tanzania",Z26:Z48) -> 0 | W13: =SUMIF($B26:$B48,"Tanzania",AA26:AA48) -> 0
A14: Massai | B14: =SUMIF(B26:B48,"Massai",E26:E48) -> 0 | C14: =SUMIF(B26:B48,"Massai",I26:I48) -> 0 | D14: =C14*B14 -> 0 | E14: =SUMIF(B26:B48,"Massai",K26:K48) -> 0 | F14: =SUMIF(B26:B48,"Massai",L26:L48) -> 0 | I14: =F14/C14 -> #DIV/0! | J14: =SUMIF(B26:B48,"Massai",N26:N48) -> 0 | K14: =J14/C14 -> #DIV/0! | L14: =SUMIF($B26:$B48,"Massai",P26:P48) -> 0 | M14: =L14/C14 -> #DIV/0! | N14: =SUMIF($B26:$B48,"Massai",R26:R48) -> 0 | O14: =SUMIF($B26:$B48,"Massai",S26:S48) -> 0 | P14: =O14/E14 -> #DIV/0! | Q14: =SUMIF($B26:$B48,"Massai",U26:U48) -> 0 | R14: =Q14/C14 -> #DIV/0! | S14: =SUMIF($B26:$B48,"Massai",W26:W48) -> 0 | T14: =SUMIF($B26:$B48,"Massai",X26:X48) -> 0 | U14: =T14/S14 -> #DIV/0! | V14: =SUMIF($B26:$B48,"Massai",Z26:Z48) -> 0 | W14: =SUMIF($B26:$B48,"Massai",AA26:AA48) -> 0
A15: Aruana | B15: =SUMIF(B26:B48,"Aruana",E26:E48) -> 0 | C15: =SUMIF(B26:B48,"Aruana",I26:I48) -> 0 | D15: =C15*B15 -> 0 | E15: =SUMIF(B26:B48,"Aruana",K26:K48) -> 0 | F15: =SUMIF(B26:B48,"Aruana",L26:L48) -> 0 | I15: =F15/C15 -> #DIV/0! | J15: =SUMIF(B26:B48,"Aruana",N26:N48) -> 0 | K15: =J15/C15 -> #DIV/0! | L15: =SUMIF($B26:$B48,"Aruana",P26:P48) -> 0 | M15: =L15/C15 -> #DIV/0! | N15: =SUMIF($B26:$B48,"Aruana",R26:R48) -> 0 | O15: =SUMIF($B26:$B48,"Aruana",S26:S48) -> 0 | P15: =O15/E15 -> #DIV/0! | Q15: =SUMIF($B26:$B48,"Aruana",U26:U48) -> 0 | R15: =Q15/C15 -> #DIV/0! | S15: =SUMIF($B26:$B48,"Aruana",W26:W48) -> 0 | T15: =SUMIF($B26:$B48,"Aruana",X26:X48) -> 0 | U15: =T15/S15 -> #DIV/0! | V15: =SUMIF($B26:$B48,"Aruana",Z26:Z48) -> 0 | W15: =SUMIF($B26:$B48,"Aruana",AA26:AA48) -> 0
A16: Zuri | B16: =SUMIF(B26:B48,"Zuri",E26:E48) -> 0 | C16: =SUMIF(B26:B48,"Zuri",I26:I48) -> 0 | D16: =C16*B16 -> 0 | E16: =SUMIF(B26:B48,"Zuri",K26:K48) -> 0 | F16: =SUMIF(B26:B48,"Zuri",L26:L48) -> 0 | I16: =F16/C16 -> #DIV/0! | J16: =SUMIF(B26:B48,"Zuri",N26:N48) -> 0 | K16: =J16/C16 -> #DIV/0! | L16: =SUMIF($B26:$B48,"Zuri",P26:P48) -> 0 | M16: =L16/C16 -> #DIV/0! | P16: =O16/E16 -> #DIV/0! | R16: =Q16/C16 -> #DIV/0! | U16: =T16/S16 -> #DIV/0!
A17: Paiaguas | B17: =SUMIF(B26:B48,"Paiaguas",E26:E48) -> 0 | C17: =SUMIF(B26:B48,"Paiaguas",I26:I48) -> 0 | D17: =C17*B17 -> 0 | E17: =SUMIF(B26:B48,"Paiaguas",K26:K48) -> 0 | F17: =SUMIF(B26:B48,"Paiaguas",L26:L48) -> 0 | I17: =F17/C17 -> #DIV/0! | J17: =SUMIF(B26:B48,"Paiaguas",N26:N48) -> 0 | K17: =J17/C17 -> #DIV/0! | L17: =SUMIF($B26:$B48,"Paiaguas",P26:P48) -> 0 | M17: =L17/C17 -> #DIV/0! | P17: =O17/E17 -> #DIV/0! | R17: =Q17/C17 -> #DIV/0! | U17: =T17/S17 -> #DIV/0!
A18: Tupi | B18: =SUMIF(B26:B48,"Tupi",E26:E48) -> 0 | C18: =SUMIF(B26:B48,"Tupi",I26:I48) -> 0 | D18: =C18*B18 -> 0 | E18: =SUMIF(B26:B48,"Tupi",K26:K48) -> 0 | F18: =SUMIF(B26:B48,"Tupi",L26:L48) -> 0 | I18: =F18/C18 -> #DIV/0! | J18: =SUMIF(B26:B48,"Tupi",N26:N48) -> 0 | K18: =J18/C18 -> #DIV/0! | L18: =SUMIF($B26:$B48,"Tupi",P26:P48) -> 0 | M18: =L18/C18 -> #DIV/0! | P18: =O18/E18 -> #DIV/0! | R18: =Q18/C18 -> #DIV/0! | U18: =T18/S18 -> #DIV/0!
A19: Estilosantes | B19: =SUMIF(B26:B48,"Estilosantes",E26:E48) -> 0 | D19: =C19*B19 -> 0 | E19: =SUMIF(B26:B48,"Estilosantes",K26:K48) -> 0 | F19: =SUMIF(B26:B48,"Estilosantes",L26:L48) -> 0 | I19: =F19/C19 -> #DIV/0! | J19: =SUMIF(B26:B48,"Estilosantes",N26:N48) -> 0 | K19: =J19/C19 -> #DIV/0! | L19: =SUMIF($B26:$B48,"Estilosantes",P26:P48) -> 0 | M19: =L19/C19 -> #DIV/0! | N19: =SUMIF($B26:$B48,"Estilosantes",R26:R48) -> 0 | O19: =SUMIF($B26:$B48,"Estilosantes",S26:S48) -> 0 | P19: =O19/E19 -> #DIV/0! | Q19: =SUMIF($B26:$B48,"Estilosantes",U26:U48) -> 0 | R19: =Q19/C19 -> #DIV/0! | S19: =SUMIF($B26:$B48,"Estilosantes",W26:W48) -> 0 | T19: =SUMIF($B26:$B48,"Estilosantes",X26:X48) -> 0 | U19: =T19/S19 -> #DIV/0! | V19: =SUMIF($B26:$B48,"Estilosantes",Z26:Z48) -> 0 | W19: =SUMIF($B26:$B48,"Estilosantes",AA26:AA48) -> 0
A20: Andropogon | B20: =SUMIF(B26:B48,"Andropogon",E26:E48) -> 0 | C20: =SUMIF(B26:B48,"Andropogon",I26:I48) -> 0 | D20: =C20*B20 -> 0 | E20: =SUMIF(B26:B48,"Andropogon",K26:K48) -> 0 | F20: =SUMIF(B26:B48,"Andropogon",L26:L48) -> 0 | I20: =F20/C20 -> #DIV/0! | J20: =SUMIF(B26:B48,"Andropogon",N26:N48) -> 0 | K20: =J20/C20 -> #DIV/0! | L20: =SUMIF($B26:$B48,"Andropogon",P26:P48) -> 0 | M20: =L20/C20 -> #DIV/0! | N20: =SUMIF($B26:$B48,"Andropogon",R26:R48) -> 0 | O20: =SUMIF($B26:$B48,"Andropogon",S26:S48) -> 0 | P20: =O20/E20 -> #DIV/0! | Q20: =SUMIF($B26:$B48,"Andropogon",U26:U48) -> 0 | R20: =Q20/C20 -> #DIV/0! | S20: =SUMIF($B26:$B48,"Andropogon",W26:W48) -> 0 | T20: =SUMIF($B26:$B48,"Andropogon",X26:X48) -> 0 | U20: =T20/S20 -> #DIV/0! | V20: =SUMIF($B26:$B48,"Andropogon",Z26:Z48) -> 0 | W20: =SUMIF($B26:$B48,"Andropogon",AA26:AA48) -> 0
A21: TOTAIS | B21: =SUM(B4:B20) -> 17194804 | C21: =D21/B21 -> 0 | D21: =SUM(D4:D20) -> 0 | E21: =SUM(E4:E20) -> 17194804 | F21: =SUM(F4:F20) -> 0 | I21: =F21/C21 -> #DIV/0! | J21: =SUM(J4:J20) -> 0 | K21: =J21/C21 -> #DIV/0! | L21: =SUM(L4:L20) -> 0 | M21: =L21/C21 -> #DIV/0! | N21: =SUM(N4:N20) -> 0 | O21: =SUM(O4:O20) -> 0 | P21: =O21/E21 -> 0 | Q21: =SUM(Q4:Q20) -> 0 | R21: =Q21/E21 -> 0 | S21: =SUM(S4:S20) -> 17194804 | T21: =SUM(T4:T20) -> 0 | U21: =T21/S21 -> 0 | V21: =SUM(V4:V20) -> 17194804 | W21: =SUM(W4:W20) -> 0
A23: RELATÓRIO DE PARCEIROS
Z24: PP | AA24: PP
A25: Data | B25: Cultivar | C25: Fornecedor | D25: Carga/Beneficiamento | E25: PP Negociado | F25: Pureza | G25: TZ | H25: TZ Total | I25: Peso Bruto | J25: Motorista | K25: PP Nosso | L25: V. Comiss R$ | M25: Comis % | N25: V. Frete R$ | O25: Frete % | P25: V. ICMS | Q25: ICMS % | R25: Dif.Compra | S25: Quebra PP | T25: %Quebra PP | U25: Custo Estetica | V25: %C.Estet. | W25: PP Pronto | X25: CUSTO TOTAL | Y25: R$/PP Total | Z25: Recebido | AA25: A Receber
A26: 45575 | B26: Ruziziensis | C26: Sierentz | D26: CG 084/24 | E26: 2818800 | F26: 67.5 | G26: 88 | H26: =I26*G26 -> 3674880 | I26: 41760 | J26: Salvador | K26: =I26*F26 -> 2818800 | L26: =M26*I26 -> 0 | O26: =N26/I26 -> 0 | Q26: =P26/I26 -> 0 | R26: =K26-E26 -> 0 | T26: =S26/K26 -> 0 | V26: =U26/I26 -> 0 | W26: =E26+R26+S26 -> 2818800 | Y26: =X26/W26 -> 0 | Z26: 2818800 | AA26: =W26-Z26 -> 0
A27: 45575 | B27: Ruziziensis | C27: Sierentz | D27: CG 086/24 | E27: 3070804 | F27: 69.1 | G27: 85 | H27: =I27*G27 -> 3777400 | I27: 44440 | J27: Gustavo | K27: =I27*F27 -> 3070804 | L27: =M27*I27 -> 0 | O27: =N27/I27 -> 0 | Q27: =P27/I27 -> 0 | T27: =S27/K27 -> 0 | V27: =U27/I27 -> 0 | W27: =E27+R27+S27 -> 3070804 | Y27: =X27/W27 -> 0 | Z27: 3070804 | AA27: =W27-Z27 -> 0
A28: 45584 | B28: Ruziziensis | C28: Sierentz | D28: CG 090/24 | E28: 3009060 | F28: 68.7 | G28: 64 | H28: =I28*G28 -> 2803200 | I28: 43800 | J28: José Valdson | K28: =I28*F28 -> 3009060 | L28: =M28*I28 -> 0 | O28: =N28/I28 -> 0 | Q28: =P28/I28 -> 0 | T28: =S28/K28 -> 0 | V28: =U28/I28 -> 0 | W28: =E28+R28+S28 -> 3009060 | Y28: =X28/W28 -> 0 | Z28: 3009060 | AA28: =W28-Z28 -> 0
A29: 45595 | B29: Ruziziensis | C29: Sierentz | D29: CG 096/24 | E29: 3481020 | F29: 83 | G29: 86 | H29: =I29*G29 -> 3606840 | I29: 41940 | J29: Salvador | K29: =I29*F29 -> 3481020 | L29: =M29*I29 -> 0 | O29: =N29/I29 -> 0 | Q29: =P29/I29 -> 0 | T29: =S29/K29 -> 0 | V29: =U29/I29 -> 0 | W29: =E29+R29+S29 -> 3481020 | Y29: =X29/W29 -> 0 | Z29: 3481020 | AA29: =W29-Z29 -> 0
A30: 45597 | B30: Ruziziensis | C30: Sierentz | D30: CG 099/24 | E30: 1693746 | F30: 65.7 | G30: 80 | H30: =I30*G30 -> 2062400 | I30: 25780 | J30: Henrique | K30: =I30*F30 -> 1693746 | L30: =M30*I30 -> 0 | O30: =N30/I30 -> 0 | Q30: =P30/I30 -> 0 | T30: =S30/K30 -> 0 | V30: =U30/I30 -> 0 | W30: =E30+R30+S30 -> 1693746 | Y30: =X30/W30 -> 0 | Z30: 1693746 | AA30: =W30-Z30 -> 0
A31: 45600 | B31: Ruziziensis | C31: Sierentz | D31: CG 101/24 | E31: 3121374 | F31: 77.3 | G31: 65 | H31: =I31*G31 -> 2624700 | I31: 40380 | J31: Gustavo | K31: =I31*F31 -> 3121374 | L31: =M31*I31 -> 0 | O31: =N31/I31 -> 0 | Q31: =P31/I31 -> 0 | T31: =S31/K31 -> 0 | V31: =U31/I31 -> 0 | W31: =E31+R31+S31 -> 3121374 | Y31: =X31/W31 -> 0 | Z31: 3121374 | AA31: =W31-Z31 -> 0
E49: =SUBTOTAL(9,E26:E48) -> 17194804 | F49: =E49/I49 -> 72.216732 | G49: =H49/I49 -> 77.906006 | H49: =SUBTOTAL(9,H26:H48) -> 18549420 | I49: =SUBTOTAL(9,I26:I48) -> 238100 | K49: =SUBTOTAL(9,K26:K48) -> 17194804 | L49: =SUBTOTAL(9,L26:L48) -> 0 | M49: =L49/I49 -> 0 | N49: =SUBTOTAL(9,N26:N48) -> 0 | O49: =N49/I49 -> 0 | P49: =SUBTOTAL(9,P26:P48) -> 0 | Q49: =P49/I49 -> 0 | R49: =SUBTOTAL(9,R26:R48) -> 0 | S49: =SUBTOTAL(9,S26:S48) -> 0 | T49: =S49/K49 -> 0 | U49: =SUBTOTAL(9,U26:U48) -> 0 | V49: =U49/M49 -> #DIV/0! | W49: =SUBTOTAL(9,W26:W48) -> 17194804 | X49: =SUBTOTAL(9,X26:X48) -> 0 | Y49: =X49/W49 -> 0 | Z49: =SUBTOTAL(9,Z26:Z48) -> 17194804 | AA49: =SUBTOTAL(9,AA26:AA48) -> 0

Sheet COM.
A1: RESUMO GERAL DE COMPRAS
A3: VARIEDADE | B3: PP NEGOCIADO | C3: VALOR PAGO | D3: R$ PP | F3: PP CHEGADA | G3: TOT. COMIS | H3: % | I3: TOT. FRETE | K3: % | L3: TOT. ICMS | M3: % | N3: TOT.DIF.COMP. | O3: QUEBRA | P3: % QUEBRA | Q3: TOT.ESTETICA | R3: % EST. | S3: PP PRONTO | T3: VALOR PAGO | U3: R$ PP REAL | V3: PP RECEBIDO | W3: PP A RECEBER
A4: Marandú | B4: =SUMIF(B32:B172,"Marandu",F32:F172) -> 27810782 | C4: =SUMIF(B32:B172,"Marandu",H32:H172) -> 6437834 | D4: =C4/B4 -> 0.23148698 | F4: =SUMIF(B32:B172,"Marandu",K32:K172) -> 27763660 | G4: =SUMIF(B32:B172,"Marandu",L32:L172) -> 14536.989 | H4: =G4/C4 -> 0.0022580559 | I4: =SUMIF(B32:B172,"Marandu",N32:N172) -> 0 | K4: =I4/C4 -> 0 | L4: =SUMIF($B32:$B172,"Marandu",P32:P172) -> 19450.78 | M4: =L4/C4 -> 0.0030213236 | N4: =SUMIF($B32:$B172,"Marandu",R32:R172) -> -47122 | O4: =SUMIF($B32:$B172,"Marandu",S32:S172) -> 0 | P4: =O4/F4 -> 0 | Q4: =SUMIF($B32:$B172,"Marandu",U32:U172) -> 0 | R4: =Q4/C4 -> 0 | S4: =SUMIF($B32:$B172,"Marandu",W32:W172) -> 27763660 | T4: =SUMIF($B32:$B172,"Marandu",X32:X172) -> 6471821.7 | U4: =T4/S4 -> 0.23310406 | V4: =SUMIF($B32:$B172,"Marandu",Z32:Z172) -> 27763660 | W4: =SUMIF($B32:$B172,"Marandu",AA32:AA172) -> -0.4
A5: Piatã | B5: =SUMIF(B32:B172,"Piatã",F32:F172) -> 20845508 | C5: =SUMIF(B32:B172,"Piatã",H32:H172) -> 4264576.5 | D5: =C5/B5 -> 0.20458012 | F5: =SUMIF(B32:B172,"Piatã",K32:K172) -> 20851571 | G5: =SUMIF(B32:B172,"Piata",L32:L172) -> 0 | H5: =G5/C5 -> 0 | I5: =SUMIF(B32:B172,"Piatã",N32:N172) -> 0 | K5: =I5/C5 -> 0 | L5: =SUMIF($B32:$B172,"Piata",P32:P172) -> 0 | M5: =L5/C5 -> 0 | N5: =SUMIF($B32:$B172,"Piatã",R32:R172) -> 6064 | O5: =SUMIF($B32:$B172,"Piatã",S32:S172) -> 0 | P5: =O5/F5 -> 0 | Q5: =SUMIF($B32:$B172,"Piatã",U32:U172) -> 0 | R5: =Q5/C5 -> 0 | S5: =SUMIF($B32:$B172,"Piatã",W32:W172) -> 20851572 | T5: =SUMIF($B32:$B172,"Piatã",X32:X172) -> 4276599.3 | U5: =T5/S5 -> 0.20509722 | V5: =SUMIF($B32:$B172,"Piatã",Z32:Z172) -> 20851571 | W5: =SUMIF($B32:$B172,"Piatã",AA32:AA172) -> 0.6
A6: Decumbens | B6: =SUMIF(B32:B172,"Decumbens",F32:F172) -> 2878952.3 | C6: =SUMIF(B32:B172,"Decumbens",H32:H172) -> 852272 | D6: =C6/B6 -> 0.29603547 | F6: =SUMIF(B32:B172,"Decumbens",K32:K172) -> 2878953.1 | G6: =SUMIF(B32:B172,"Decumbens",L32:L172) -> 0 | H6: =G6/C6 -> 0 | I6: =SUMIF(B32:B172,"Decumbens",N32:N172) -> 0 | K6: =I6/C6 -> 0 | L6: =SUMIF($B32:$B172,"Decumbens",P32:P172) -> 0 | M6: =L6/C6 -> 0 | N6: =SUMIF($B32:$B172,"Decumbens",R32:R172) -> 1 | O6: =SUMIF($B32:$B172,"Decumbens",S32:S172) -> 0 | P6: =O6/F6 -> 0 | Q6: =SUMIF($B32:$B172,"Decumbens",U32:U172) -> 0 | R6: =Q6/C6 -> 0 | S6: =SUMIF($B32:$B172,"Decumbens",W32:W172) -> 2878953.3 | T6: =SUMIF($B32:$B172,"Decumbens",X32:X172) -> 852272 | U6: =T6/S6 -> 0.29603536 | V6: =SUMIF($B32:$B172,"Decumbens",Z32:Z172) -> 2878953.1 | W6: =SUMIF($B32:$B172,"Decumbens",AA32:AA172) -> 0.23739936
A7: Xaraes | B7: =SUMIF(B32:B172,"Xaraes",F32:F172) -> 8958232 | C7: =SUMIF(B32:B172,"Xaraes",H32:H172) -> 1716349.6 | D7: =C7/B7 -> 0.19159468 | F7: =SUMIF(B32:B172,"Xaraes",K32:K172) -> 8985247.8 | G7: =SUMIF(B32:B172,"Xaraes",L32:L172) -> 11293.613 | H7: =G7/C7 -> 0.0065800189 | I7: =SUMIF(B32:B172,"Xaraes",N32:N172) -> 0 | K7: =I7/C7 -> 0 | L7: =SUMIF($B32:$B172,"Xaraes",P32:P172) -> 17166.3 | M7: =L7/C7 -> 0.010001634 | N7: =SUMIF($B32:$B172,"Xaraes",R32:R172) -> 27016 | O7: =SUMIF($B32:$B172,"Xaraes",S32:S172) -> 0 | P7: =O7/F7 -> 0 | Q7: =SUMIF($B32:$B172,"Xaraes",U32:U172) -> 0 | R7: =Q7/C7 -> 0 | S7: =SUMIF($B32:$B172,"Xaraes",W32:W172) -> 8985248 | T7: =SUMIF($B32:$B172,"Xaraes",X32:X172) -> 1744809.5 | U7: =T7/S7 -> 0.19418602 | V7: =SUMIF($B32:$B172,"Xaraes",Z32:Z172) -> 8985247.8 | W7: =SUMIF($B32:$B172,"Xaraes",AA32:AA172) -> 0.25
A8: MG-4 | B8: =SUMIF(B32:B172,"MG-4",F32:F172) -> 0 | C8: =SUMIF(B32:B172,"MG-4",H32:H172) -> 0 | D8: =C8/B8 -> #DIV/0! | F8: =SUMIF(B32:B172,"MG-4",K32:K172) -> 0 | G8: =SUMIF(B32:B172,"MG-4",L32:L172) -> 0 | H8: =G8/C8 -> #DIV/0! | I8: =SUMIF(B32:B172,"MG-4",N32:N172) -> 0 | K8: 0 | L8: =SUMIF($B32:$B172,"MG-4",P32:P172) -> 0 | M8: 0 | N8: =SUMIF($B32:$B172,"MG-4",R32:R172) -> 0 | O8: =SUMIF($B32:$B172,"MG-4",S32:S172) -> 0 | P8: =O8/F8 -> #DIV/0! | Q8: =SUMIF($B32:$B172,"MG-4",U32:U172) -> 0 | R8: =Q8/C8 -> #DIV/0! | S8: =SUMIF($B32:$B172,"MG-4",W32:W172) -> 0 | T8: =SUMIF($B32:$B172,"MG-4",X32:X172) -> 0 | U8: =T8/S8 -> #DIV/0! | V8: =SUMIF($B32:$B172,"MG-4",Z32:Z172) -> 0 | W8: =SUMIF($B32:$B172,"MG-4",AA32:AA172) -> 0
A9: Ruziziensis | B9: =SUMIF(B32:B172,"Ruziziensis",F32:F172) -> 81427743 | C9: =SUMIF(B32:B172,"Ruziziensis",H32:H172) -> 7436104.3 | D9: =C9/B9 -> 0.091321508 | F9: =SUMIF(B32:B172,"Ruziziensis",K32:K172) -> 81427743 | G9: =SUMIF(B32:B172,"Ruziziensis",L32:L172) -> 0 | H9: =G9/C9 -> 0 | I9: =SUMIF(B32:B172,"Ruziziensis",N32:N172) -> 0 | K9: =I9/C9 -> 0 | L9: =SUMIF($B32:$B172,"Ruziziensis",P32:P172) -> 0 | M9: =L9/C9 -> 0 | N9: =SUMIF($B32:$B172,"Ruziziensis",R32:R172) -> 0 | O9: =SUMIF($B32:$B172,"Ruziziensis",S32:S172) -> 0 | P9: =O9/F9 -> 0 | Q9: =SUMIF($B32:$B172,"Ruziziensis",U32:U172) -> 0 | R9: =Q9/C9 -> 0 | S9: =SUMIF($B32:$B172,"Ruziziensis",W32:W172) -> 81427743 | T9: =SUMIF($B32:$B172,"Ruziziensis",X32:X172) -> 7436104.3 | U9: =T9/S9 -> 0.091321508 | V9: =SUMIF($B32:$B172,"Ruziziensis",Z32:Z172) -> 81427743 | W9: =SUMIF($B32:$B172,"Ruziziensis",AA32:AA172) -> 0
A10: Humidicola | B10: =SUMIF(B32:B172,"Humidicola",F32:F172) -> 844343.76 | C10: =SUMIF(B32:B172,"humidicola",H32:H172) -> 1657890.5 | D10: =C10/B10 -> 1.9635255 | F10: =SUMIF(B32:B178,"Humidicola",K32:K172) -> 845306.31 | G10: =SUMIF(B32:B172,"humidicola",L32:L172) -> 0 | H10: =G10/C10 -> 0 | I10: =SUMIF(B32:B172,"humidicola",N32:N172) -> 0 | K10: =I10/C10 -> 0 | L10: =SUMIF($B32:$B172,"Humidicola",P32:P172) -> 0 | M10: =L10/C10 -> 0 | N10: =SUMIF($B32:$B172,"Humidicola",R32:R172) -> 963 | O10: =SUMIF($B32:$B172,"Humidicola",S32:S172) -> 0 | P10: =O10/F10 -> 0 | Q10: =SUMIF($B32:$B172,"Humidicola",U32:U172) -> 0 | R10: =Q10/C10 -> 0 | S10: =SUMIF($B32:$B172,"Humidicola",W32:W172) -> 845306.76 | T10: =SUMIF($B32:$B172,"Humidicola",X32:X172) -> 1657890.5 | U10: =T10/S10 -> 1.9612886 | V10: =SUMIF($B32:$B172,"Humidicola",Z32:Z172) -> 845306.31 | W10: =SUMIF($B32:$B172,"Humidicola",AA32:AA172) -> 0.454
A11: Llanero | B11: =SUMIF(B32:B172,"Llanero",F32:F172) -> 384600 | C11: =SUMIF(B32:B172,"Llanero",H32:H172) -> 878758.24 | D11: =C11/B11 -> 2.2848628 | F11: =SUMIF(B32:B172,"Llanero",K32:K172) -> 384600 | G11: =SUMIF(B32:B172,"Llanero",L32:L172) -> 0 | H11: =G11/C11 -> 0 | I11: =SUMIF(B32:B172,"Llanero",N32:N172) -> 0 | K11: =I11/C11 -> 0 | L11: =SUMIF($B32:$B172,"Llanero",P32:P172) -> 0 | M11: =L11/C11 -> 0 | N11: =SUMIF($B32:$B172,"Llanero",R32:R172) -> 0 | O11: =SUMIF($B32:$B172,"Llanero",S32:S172) -> 0 | P11: =O11/F11 -> 0 | Q11: =SUMIF($B32:$B172,"Llanero",U32:U172) -> 0 | R11: =Q11/C11 -> 0 | S11: =SUMIF($B32:$B172,"Llanero",W32:W172) -> 384600 | T11: =SUMIF($B32:$B172,"Llanero",X32:X172) -> 878758.24 | U11: =T11/S11 -> 2.2848628 | V11: =SUMIF($B32:$B172,"Llanero",Z32:Z172) -> 384600 | W11: =SUMIF($B32:$B172,"Llanero",AA32:AA172) -> 0
A12: Mombaça | B12: =SUMIF(B32:B172,"Mombaça",F32:F172) -> 14646502 | C12: =SUMIF(B32:B172,"Mombaça",H32:H172) -> 3022318.8 | D12: =C12/B12 -> 0.2063509 | F12: =SUMIF(B32:B172,"Mombaça",K32:K172) -> 14483843 | G12: =SUMIF(B32:B172,"Mombaça",L32:L172) -> 4247.735 | H12: =G12/C12 -> 0.0014054556 | I12: =SUMIF(B32:B172,"Mombaça",N32:N172) -> 0 | K12: =I12/C12 -> 0 | L12: =SUMIF($B32:$B172,"Mombaça",P32:P172) -> 4757.46 | M12: =L12/C12 -> 0.0015741092 | N12: =SUMIF($B32:$B172,"Mombaça",R32:R172) -> -162659.5 | O12: =SUMIF($B32:$B172,"Mombaça",S32:S172) -> 0 | P12: =O12/F12 -> 0 | Q12: =SUMIF($B32:$B172,"Mombaça",U32:U172) -> 0 | R12: =Q12/C12 -> 0 | S12: =SUMIF($B32:$B172,"Mombaça",W32:W172) -> 14483842 | T12: =SUMIF($B32:$B172,"Mombaça",X32:X172) -> 3031324 | U12: =T12/S12 -> 0.20929004 | V12: =SUMIF($B32:$B172,"Mombaça",Z32:Z172) -> 14483843 | W12: =SUMIF($B32:$B172,"Mombaça",AA32:AA172) -> -0.5
A13: Tanzania | B13: =SUMIF(B32:B172,"Tanzania",F32:F172) -> 0 | C13: =SUMIF(B32:B172,"Tanzania",H32:H172) -> 0 | D13: =C13/B13 -> #DIV/0! | F13: =SUMIF(B32:B172,"Tanzania",K32:K172) -> 0 | G13: =SUMIF(B32:B172,"Tanzania",L32:L172) -> 0 | H13: =G13/C13 -> #DIV/0! | I13: =SUMIF(B32:B172,"Tanzania",N32:N172) -> 0 | K13: =I13/C13 -> #DIV/0! | L13: =SUMIF($B32:$B172,"Tanzania",P32:P172) -> 0 | M13: =L13/C13 -> #DIV/0! | N13: =SUMIF($B32:$B172,"Tanzania",R32:R172) -> 0 | O13: =SUMIF($B32:$B172,"Tanzania",S32:S172) -> 0 | P13: =O13/F13 -> #DIV/0! | Q13: =SUMIF($B32:$B172,"Tanzania",U32:U172) -> 0 | R13: =Q13/C13 -> #DIV/0! | S13: =SUMIF($B32:$B172,"Tanzania",W32:W172) -> 0 | T13: =SUMIF($B32:$B172,"Tanzania",X32:X172) -> 0 | U13: =T13/S13 -> #DIV/0! | V13: =SUMIF($B32:$B172,"Tanzania",Z32:Z172) -> 0 | W13: =SUMIF($B32:$B172,"Tanzania",AA32:AA172) -> 0
A14: Massai | B14: =SUMIF(B32:B172,"Massai",F32:F172) -> 5816385 | C14: =SUMIF(B32:B172,"Massai",H32:H172) -> 1785738.1 | D14: =C14/B14 -> 0.30701855 | F14: =SUMIF(B32:B172,"Massai",K32:K172) -> 5952144.8 | G14: =SUMIF(B32:B172,"Massai",L32:L172) -> 3242.05 | H14: =G14/C14 -> 0.0018155238 | I14: =SUMIF(B32:B172,"Massai",N32:N172) -> 0 | K14: =I14/C14 -> 0 | L14: =SUMIF($B32:$B172,"Massai",P32:P172) -> 3631.09 | M14: =L14/C14 -> 0.0020333833 | N14: =SUMIF($B32:$B172,"Massai",R32:R172) -> 135759.8 | O14: =SUMIF($B32:$B172,"Massai",S32:S172) -> 0 | P14: =O14/F14 -> 0 | Q14: =SUMIF($B32:$B172,"Massai",U32:U172) -> 0 | R14: =Q14/C14 -> 0 | S14: =SUMIF($B32:$B172,"Massai",W32:W172) -> 5952144.8 | T14: =SUMIF($B32:$B172,"Massai",X32:X172) -> 1792611.2 | U14: =T14/S14 -> 0.30117064 | V14: =SUMIF($B32:$B172,"Massai",Z32:Z172) -> 5952144.8 | W14: =SUMIF($B32:$B172,"Massai",AA32:AA172) -> 0
A15: Aruana | B15: =SUMIF(B32:B172,"Aruana",F32:F172) -> 701127.4 | C15: =SUMIF(B32:B172,"Aruana",H32:H172) -> 298278.35 | D15: =C15/B15 -> 0.42542675 | F15: =SUMIF(B32:B172,"Aruana",K32:K172) -> 701127.4 | G15: =SUMIF(B32:B172,"Aruana",L32:L172) -> 0 | H15: =G15/C15 -> 0 | I15: =SUMIF(B32:B172,"Aruana",N32:N172) -> 2240 | K15: 0 | L15: =SUMIF($B32:$B172,"Aruana",P32:P172) -> 2159.13 | M15: 0 | N15: =SUMIF($B32:$B172,"Aruana",R32:R172) -> 0 | O15: =SUMIF($B32:$B172,"Aruana",S32:S172) -> 0 | P15: =O15/F15 -> 0 | Q15: =SUMIF($B32:$B172,"Aruana",U32:U172) -> 0 | R15: =Q15/C15 -> 0 | S15: =SUMIF($B32:$B172,"Aruana",W32:W172) -> 701127.4 | T15: =SUMIF($B32:$B172,"Aruana",X32:X172) -> 302677.48 | U15: =T15/S15 -> 0.43170111 | V15: =SUMIF($B32:$B172,"Aruana",Z32:Z172) -> 701127.4 | W15: =SUMIF($B32:$B172,"Aruana",AA32:AA172) -> 0
A16: Zuri | B16: =SUMIF(B32:B172,"Zuri",F32:F172) -> 4846635.2 | C16: =SUMIF(B32:B172,"Zuri",H32:H172) -> 954965.44 | D16: =C16/B16 -> 0.19703679 | F16: =SUMIF(B32:B172,"Zuri",K32:K172) -> 4846635.2 | G16: =SUMIF(B32:B172,"Zuri",L32:L172) -> 0 | H16: =G16/C16 -> 0 | I16: =SUMIF(B32:B172,"Zuri",N32:N172) -> 0 | K16: =I16/C16 -> 0 | L16: =SUMIF($B32:$B172,"Zuri",P32:P172) -> 0 | M16: =L16/C16 -> 0 | N16: =SUMIF($B32:$B172,"Zuri",R32:R172) -> 0 | O16: =SUMIF($B32:$B172,"Zuri",S32:S172) -> 0 | P16: =O16/F16 -> 0 | Q16: =SUMIF($B32:$B172,"Zuri",U32:U172) -> 0 | R16: =Q16/C16 -> 0 | S16: =SUMIF($B32:$B172,"Zuri",W32:W172) -> 4846635.2 | T16: =SUMIF($B32:$B172,"Zuri",X32:X172) -> 954965.44 | U16: =T16/S16 -> 0.19703679 | V16: =SUMIF($B32:$B172,"Zuri",Z32:Z172) -> 4846635.2 | W16: =SUMIF($B32:$B172,"Zuri",AA32:AA172) -> 0
A17: Paiaguas | B17: =SUMIF(B32:B172,"Paiaguas",F32:F172) -> 2063772 | C17: =SUMIF(B32:B172,"Paiaguas",H32:H172) -> 700000 | D17: =C17/B17 -> 0.33918475 | F17: =SUMIF(B32:B172,"Paiaguas",K32:K172) -> 2063772 | G17: =SUMIF(B32:B172,"Paiaguas",L32:L172) -> 0 | H17: =G17/C17 -> 0 | I17: =SUMIF(B32:B172,"Piaguas",N32:N172) -> 0 | K17: 0 | L17: =SUMIF($B32:$B172,"Paiaguas",P32:P172) -> 0 | M17: 0 | N17: =SUMIF($B32:$B172,"Paiaguas",R32:R172) -> 0 | O17: =SUMIF($B32:$B172,"Paiaguas",S32:S172) -> 0 | P17: =O17/F17 -> 0 | Q17: =SUMIF($B32:$B172,"Paiaguas",U32:U172) -> 0 | R17: =Q17/C17 -> 0 | S17: =SUMIF($B32:$B172,"Paiaguas",W32:W172) -> 2063772 | T17: =SUMIF($B32:$B172,"Paiaguas",X32:X172) -> 700000 | U17: =T17/S17 -> 0.33918475 | V17: =SUMIF($B32:$B172,"Paiaguas",Z32:Z172) -> 2063772 | W17: =SUMIF($B32:$B172,"Paiaguas",AA32:AA172) -> 0
A18: Tamani | B18: =SUMIF(B32:B172,"Tamani",F32:F172) -> 1673479.2 | C18: =SUMIF(B32:B172,"Tamani",H32:H172) -> 602452.51 | D18: =C18/B18 -> 0.36 | F18: =SUMIF(B32:B172,"Tamani",K32:K172) -> 1673479.2 | G18: =SUMIF(B32:B172,"Tamani",L32:L172) -> 0 | H18: =G18/C18 -> 0 | I18: =SUMIF(B32:B172,"Tamani",N32:N172) -> 0 | K18: =I18/C18 -> 0 | L18: =SUMIF($B32:$B172,"Tamani",P32:P172) -> 29509.92 | M18: =L18/C18 -> 0.048982981 | N18: =SUMIF($B32:$B172,"Tamani",R32:R172) -> 0 | O18: =SUMIF($B32:$B172,"Tamani",S32:S172) -> 0 | P18: =O18/F18 -> 0 | Q18: =SUMIF($B32:$B172,"Tamani",U32:U172) -> 0 | R18: =Q18/C18 -> 0 | S18: =SUMIF($B32:$B172,"Tamani",W32:W172) -> 1673479.2 | T18: =SUMIF($B32:$B172,"Tamani",X32:X172) -> 631962.43 | U18: =T18/S18 -> 0.37763387 | V18: =SUMIF($B32:$B172,"Tamani",Z32:Z172) -> 1673479.2 | W18: =SUMIF($B32:$B172,"Tamani",AA32:AA172) -> 0
A19: Integra | B19: =SUMIF(B32:B172,"Integra",F32:F172) -> 0 | C19: =SUMIF(B32:B172,"Integra",H32:H172) -> 0 | D19: =C19/B19 -> #DIV/0! | F19: =SUMIF(B32:B172,"Integra",K32:K172) -> 0 | G19: =SUMIF(B32:B172,"Integra",L32:L172) -> 0 | H19: =G19/C19 -> #DIV/0! | I19: =SUMIF(B32:B172,"Integra",N32:N172) -> 0 | K19: =I19/C19 -> #DIV/0! | L19: =SUMIF($B32:$B172,"Integra",P32:P172) -> 0 | M19: =L19/C19 -> #DIV/0! | N19: =SUMIF($B32:$B172,"Integra",R32:R172) -> 0 | O19: =SUMIF($B32:$B172,"Integra",S32:S172) -> 0 | P19: =O19/F19 -> #DIV/0! | Q19: =SUMIF($B32:$B172,"Integra",U32:U172) -> 0 | R19: =Q19/C19 -> #DIV/0! | S19: =SUMIF($B32:$B172,"Integra",W32:W172) -> 0 | T19: =SUMIF($B32:$B172,"Integra",X32:X172) -> 0 | U19: =T19/S19 -> #DIV/0! | V19: =SUMIF($B32:$B172,"Integra",Z32:Z172) -> 0 | W19: =SUMIF($B32:$B172,"Integra",AA32:AA172) -> 0
A20: Quenia | B20: =SUMIF(B32:B172,"Quenia",F32:F172) -> 458408 | C20: =SUMIF(B32:B172,"Quenia",H32:H172) -> 347759 | D20: =C20/B20 -> 0.75862332 | F20: =SUMIF(B32:B172,"Quenia",K32:K172) -> 458408 | G20: =SUMIF(B32:B172,"Quenia",L32:L172) -> 0 | H20: =G20/C20 -> 0 | I20: =SUMIF(B32:B172,"Quenia",N32:N172) -> 0 | K20: =I20/C20 -> 0 | L20: =SUMIF($B32:$B172,"Quenia",P32:P172) -> 0 | M20: =L20/C20 -> 0 | N20: =SUMIF($B32:$B172,"Quenia",R32:R172) -> 0 | O20: =SUMIF($B32:$B172,"Quenia",S32:S172) -> 0 | P20: =O20/F20 -> 0 | Q20: =SUMIF($B32:$B172,"Quenia",U32:U172) -> 0 | R20: =Q20/C20 -> 0 | S20: =SUMIF($B32:$B172,"Quenia",W32:W172) -> 458408 | T20: =SUMIF($B32:$B172,"Quenia",X32:X172) -> 347759 | U20: =T20/S20 -> 0.75862332 | V20: =SUMIF($B32:$B172,"Quenia",Z32:Z172) -> 458407.9 | W20: =SUMIF($B32:$B172,"Quenia",AA32:AA172) -> 0.1
A21: Sorgo | B21: =SUMIF(B32:B172,"Sorgo",F32:F172) -> 4000 | C21: =SUMIF(B32:B172,"Sorgo",H32:H172) -> 44000 | D21: =C21/B21 -> 11 | F21: =SUMIF(B32:B172,"Sorgo",K32:K172) -> 4000 | G21: =SUMIF(B32:B172,"Sorgo",L32:L172) -> 0 | H21: =G21/C21 -> 0 | I21: =SUMIF(B32:B172,"Sorgo",N32:N172) -> 0 | K21: =I21/C21 -> 0 | L21: =SUMIF($B32:$B172,"Sorgo",P32:P172) -> 0 | M21: =L21/C21 -> 0 | N21: =SUMIF($B32:$B172,"Sorgo",R32:R172) -> 0 | O21: =SUMIF($B32:$B172,"Sorgo",S32:S172) -> 0 | P21: =O21/F21 -> 0 | Q21: =SUMIF($B32:$B172,"Sorgo",U32:U172) -> 0 | R21: =Q21/C21 -> 0 | S21: =SUMIF($B32:$B172,"Sorgo",W32:W172) -> 4000 | T21: =SUMIF($B32:$B172,"Sorgo",X32:X172) -> 44000 | U21: =T21/S21 -> 11 | V21: =SUMIF($B32:$B172,"Sorgo",Z32:Z172) -> 4000 | W21: =SUMIF($B32:$B172,"Sorgo",AA32:AA172) -> 0
A22: Crotalaria | B22: =SUMIF(B32:B172,"Crotalaria",F32:F172) -> 0 | C22: =SUMIF(B32:B172,"Crotalaria",H32:H172) -> 0 | D22: =C22/B22 -> #DIV/0! | F22: =SUMIF(B32:B172,"Crotalaria",K32:K172) -> 0 | G22: =SUMIF(B32:B172,"Crotalaria",L32:L172) -> 0 | H22: =G22/C22 -> #DIV/0! | I22: =SUMIF(B32:B172,"Crotalaria",N32:N172) -> 0 | K22: =I22/C22 -> #DIV/0! | L22: =SUMIF($B32:$B172,"Crotalaria",P32:P172) -> 0 | M22: =L22/C22 -> #DIV/0! | N22: =SUMIF($B32:$B172,"Crotalaria",R32:R172) -> 0 | O22: =SUMIF($B32:$B172,"Crotalaria",S32:S172) -> 0 | P22: =O22/F22 -> #DIV/0! | Q22: =SUMIF($B32:$B172,"Crotalaria",U32:U172) -> 0 | R22: =Q22/C22 -> #DIV/0! | S22: =SUMIF($B32:$B172,"Crotalaria",W32:W172) -> 0 | T22: =SUMIF($B32:$B172,"Crotalaria",X32:X172) -> 0 | U22: =T22/S22 -> #DIV/0! | V22: =SUMIF($B32:$B172,"Crotalaria",Z32:Z172) -> 0 | W22: =SUMIF($B32:$B172,"Crotalaria",AA32:AA172) -> 0
A23: Estilosantes | B23: =SUMIF(B32:B172,"Estilosantes",F32:F172) -> 0 | C23: =SUMIF(B32:B172,"Estilosantes",H32:H172) -> 0 | D23: =C23/B23 -> #DIV/0! | F23: =SUMIF(B32:B172,"Estilosantes",K32:K172) -> 0 | G23: =SUMIF(B32:B172,"Estilosantes",L32:L172) -> 0 | H23: =G23/C23 -> #DIV/0! | I23: =SUMIF(B32:B172,"Estilosantes",N32:N172) -> 0 | K23: =I23/C23 -> #DIV/0! | L23: =SUMIF($B32:$B172,"Estilosantes",P32:P172) -> 0 | M23: =L23/C23 -> #DIV/0! | N23: =SUMIF($B32:$B172,"Estilosantes",R32:R172) -> 0 | O23: =SUMIF($B32:$B172,"Estilosantes",S32:S172) -> 0 | P23: =O23/F23 -> #DIV/0! | Q23: =SUMIF($B32:$B172,"Estilosantes",U32:U172) -> 0 | R23: =Q23/C23 -> #DIV/0! | S23: =SUMIF($B32:$B172,"Estilosantes",W32:W172) -> 0 | T23: =SUMIF($B32:$B172,"Estilosantes",X32:X172) -> 0 | U23: =T23/S23 -> #DIV/0! | V23: =SUMIF($B32:$B172,"Estilosantes",Z32:Z172) -> 0 | W23: =SUMIF($B32:$B172,"Estilosantes",AA32:AA172) -> 0
A24: Milheto | B24: =SUMIF(B32:B172,"Milheto",F32:F172) -> 43500 | C24: =SUMIF(B32:B172,"Milheto",H32:H172) -> 104750 | D24: =C24/B24 -> 2.408046 | F24: =SUMIF(B32:B172,"Milheto",K32:K172) -> 43500 | G24: =SUMIF(B32:B172,"Milheto",L32:L172) -> 0 | H24: =G24/C24 -> 0 | I24: =SUMIF(B32:B172,"Milheto",N32:N172) -> 0 | K24: =I24/C24 -> 0 | L24: =SUMIF($B32:$B172,"Milheto",P32:P172) -> 0 | M24: =L24/C24 -> 0 | N24: =SUMIF($B32:$B172,"Milheto",R32:R172) -> 0 | O24: =SUMIF($B32:$B172,"Milheto",S32:S172) -> 0 | P24: =O24/F24 -> 0 | Q24: =SUMIF($B32:$B172,"Milheto",U32:U172) -> 0 | R24: =Q24/C24 -> 0 | S24: =SUMIF($B32:$B172,"Milheto",W32:W172) -> 43500 | T24: =SUMIF($B32:$B172,"Milheto",X32:X172) -> 104750 | U24: =T24/S24 -> 2.408046 | V24: =SUMIF($B32:$B172,"Milheto",Z32:Z172) -> 43500 | W24: =SUMIF($B32:$B172,"Milheto",AA32:AA172) -> 0
A25: Sudão | B25: =SUMIF(B32:B172,"Sudão",F32:F172) -> 0 | C25: =SUMIF(B32:B172,"Sudão",H32:H172) -> 0 | D25: =C25/B25 -> #DIV/0! | F25: =SUMIF(B32:B172,"Sudão",K32:K172) -> 0 | G25: =SUMIF(B32:B172,"Sudão",L32:L172) -> 0 | H25: =G25/C25 -> #DIV/0! | I25: =SUMIF(B32:B172,"Sudão",N32:N172) -> 0 | K25: =I25/C25 -> #DIV/0! | L25: =SUMIF($B32:$B172,"Sudão",P32:P172) -> 0 | M25: =L25/C25 -> #DIV/0! | N25: =SUMIF($B32:$B172,"Sudão",R32:R172) -> 0 | O25: =SUMIF($B32:$B172,"Sudão",S32:S172) -> 0 | P25: =O25/F25 -> #DIV/0! | Q25: =SUMIF($B32:$B172,"Sudão",U32:U172) -> 0 | R25: =Q25/C25 -> #DIV/0! | S25: =SUMIF($B32:$B172,"Sudão",W32:W172) -> 0 | T25: =SUMIF($B32:$B172,"Sudão",X32:X172) -> 0 | U25: =T25/S25 -> #DIV/0! | V25: =SUMIF($B32:$B172,"Sudão",Z32:Z172) -> 0 | W25: =SUMIF($B32:$B172,"Sudão",AA32:AA172) -> 0
A26: Andropogon | B26: =SUMIF(B32:B172,"Andropogon",F32:F172) -> 0 | C26: =SUMIF(B32:B172,"Andropogon",H32:H172) -> 0 | D26: =C26/B26 -> #DIV/0! | F26: =SUMIF(B32:B172,"Andropogon",K32:K172) -> 0 | G26: =SUMIF(B32:B172,"Andropogon",L32:L172) -> 0 | H26: =G26/C26 -> #DIV/0! | I26: =SUMIF(B32:B172,"Andropogon",N32:N172) -> 0 | K26: =I26/C26 -> #DIV/0! | L26: =SUMIF($B32:$B172,"Andropogon",P32:P172) -> 0 | M26: =L26/C26 -> #DIV/0! | N26: =SUMIF($B32:$B172,"Andropogon",R32:R172) -> 0 | O26: =SUMIF($B32:$B172,"Andropogon",S32:S172) -> 0 | P26: =O26/F26 -> #DIV/0! | Q26: =SUMIF($B32:$B172,"Andropogon",U32:U172) -> 0 | R26: =Q26/C26 -> #DIV/0! | S26: =SUMIF($B32:$B172,"Andropogon",W32:W172) -> 0 | T26: =SUMIF($B32:$B172,"Andropogon",X32:X172) -> 0 | U26: =T26/S26 -> #DIV/0! | V26: =SUMIF($B32:$B172,"Andropogon",Z32:Z172) -> 0 | W26: =SUMIF($B32:$B172,"Andropogon",AA32:AA172) -> 0
A27: TOTAIS | B27: =SUM(B4:B26) -> 1.7340397e+08 | C27: =SUM(C4:C26) -> 31104047 | D27: =C27/B27 -> 0.17937333 | F27: =SUM(F4:F26) -> 1.7336399e+08 | G27: =SUM(G4:G26) -> 33320.387 | H27: =G27/C27 -> 0.0010712557 | I27: =SUM(I4:I26) -> 2240 | K27: =I27/C27 -> 7.2016351e-05 | L27: =SUM(L4:L26) -> 76674.68 | M27: =L27/C27 -> 0.002465103 | N27: =SUM(N4:N26) -> -39977.7 | O27: =SUM(O4:O26) -> 0 | P27: =O27/F27 -> 0 | Q27: =SUM(Q4:Q26) -> 0 | R27: =Q27/C27 -> 0 | S27: =SUM(S4:S26) -> 1.7336399e+08 | T27: =SUM(T4:T26) -> 31228305 | U27: =T27/S27 -> 0.18013144 | V27: =SUM(V4:V26) -> 1.7336399e+08 | W27: =SUM(W4:W26) -> 0.74139936
A29: RELATÓRIO DE COMPRAS
Z30: PP | AA30: PP
A31: Data | B31: Cultivar | C31: Fornecedor | D31: Carga | E31: KG | F31: PP Chegada | G31: R$/PP | H31: Total R$ | I31: Pureza | J31: Tz | K31: PP REAL | L31: V. Comiss R$ | M31: Comis % | N31: V. Frete R$ | O31: Frete % | P31: V. ICMS | Q31: ICMS % | R31: Dif.Compra | S31: Quebra PP | T31: %Quebra PP | U31: Custo Estetica | V31: %C.Estet. | W31: PP Pronto | X31: CUSTO TOTAL | Y31: R$/PP Total | Z31: Recebido | AA31: A Receber
A32: 45449 | B32: Humidicola | C32: Sementes SB | D32: CG 012-013/24 | E32: 13600 | F32: =E32*I32 -> 654540.8 | G32: =H32/F32 -> 1.65 | H32: 1079992.3 | I32: 48.128 | K32: 655503.31 | L32: =M32*H32 -> 0 | O32: =N32/H32 -> 0 | Q32: =P32/H32 -> 0 | R32: 963 | T32: =S32/K32 -> 0 | W32: =F32+R32+S32 -> 655503.8 | X32: =H32+L32+N32+P32+U32 -> 1079992.3 | Y32: =X32/W32 -> 1.647576 | Z32: 655503.31 | AA32: =W32-Z32 -> 0.494
